Workbook

Sheet Sources
A1: SOURCES — données brutes recopiées des pièces primaires
A2: SARL LA DEMI LUNE — grief O « Perte de bières ». Valeurs en dur = recopiées des sources ; tout résultat est calculé par formule dans l'onglet « Calcul ».
A4: A. Quantités de caisse 2022-2023 — SOURCE PRIMAIRE : ANNEXE-C1 (détail des tickets), agrégation par référence article
A5: Réf. | B5: Article de caisse (libellé C1) | C5: Qté 2022-2023
A6: 2005 | B6: pression | C6: 901.5
A7: 1989 | B7: Pinte | C7: 282.5
A8: 0099 | B8: Panaché | C8: 147
A9: 0353 | B9: Picon bière | C9: 129
A10: 1991 | B10: Pinte Picon | C10: 37
A11: 0354 | B11: Monaco | C11: 66.5
B12: TOTAL unités 2022-2023 | C12: =SUM(C6:C11)
A14: B. Quantités de caisse 2024-2025 — SOURCE : annexe finale du service, bloc « i)-INGREDIENT : BIERE » (OCR Proposition 4, p. 2)
A15: Réf. | B15: Article (annexe finale) | C15: Qté 2024-2025 | D15: Vol. porté (cl) | E15: Proportion
A16: 0353 | B16: Picon bière (3cl picon + 22cl) | C16: 124 | D16: 2728 | E16: 6,97 %
A17: 0099 | B17: Panaché (11cl bière) + 13cl limonade | C17: 97 | D17: 767 | E17: 1,96 %
A18: 0354 | B18: Monaco (15cl bière) + limonade + grenadine | C18: 74 | D18: 1110 | E18: 2,84 %
A19: 1991 | B19: Pinte Picon (6cl picon + 44cl) | C19: 59 | D19: 2596 | E19: 6,63 %
A20: 2005 | B20: Pression (25cl) | C20: 662 | D20: 16550 | E20: 42,27 %
A21: 1989 | B21: Pinte (50cl) | C21: 308 | D21: 15400 | E21: 39,33 %
B22: TOTAL volume porté (cl) | D22: =SUM(D16:D21)
B23: Note : panaché porté à 767 cl là où 97 × 11 = 1 067 cl (écart 300 cl retenu contre la société).
A25: C. Quantités de caisse 2023-2024 — C2 ABSENT du dossier : valeurs reprises de la pièce R1, NON VÉRIFIABLES
A26: Réf. | B26: Article | C26: Qté 2023-2024 (à étayer)
A27: 2005 | B27: pression | C27: 670
A28: 1989 | B28: Pinte | C28: 286.5
A29: 0099 | B29: Panaché | C29: 102.5
A30: 0353 | B30: Picon bière | C30: 130
A31: 1991 | B31: Pinte Picon | C31: 66.5
A32: 0354 | B32: Monaco | C32: 56
A34: D. Doses retenues (cl) — service : proposition p. 50 ; défense : part bière effective
A35: Article | B35: Contenance verre (cl) | C35: Part bière SERVICE (cl) | D35: Part bière DÉFENSE (cl)
A36: Pression (25cl) | B36: 25 | C36: 25 | D36: 25
A37: Pinte (50cl) | B37: 50 | C37: 50 | D37: 50
A38: Panaché | B38: 25 | C38: 11 | D38: 12.5
A39: Picon bière | B39: 25 | C39: 22 | D39: 21
A40: Pinte Picon | B40: 50 | C40: 44 | D40: 42
A41: Monaco | B41: 25 | C41: 15 | D41: 12.5
A43: E. Fûts Affligem Blade 8 L achetés — factures Franche-Comté Boissons Services
A44: Exercice | B44: Fûts achetés | C44: Litres achetés
A45: 2022-2023 | B45: 99 | C45: =B45*8
...

Sheet Calcul
A1: CALCUL — tous les résultats sont des formules renvoyant à l'onglet « Sources »
A3: 1. Assiette « bière réellement sortie du fût », 2022-2023 (PRIMAIRE C1)
A4: Article | B4: Qté C1 | C4: Contenance (L) | D4: Doses service (L) | E4: Nos doses (L)
A5: =Sources!B6 | B5: =Sources!C6 | C5: =Sources!C6*Sources!B36/100 | D5: =Sources!C6*Sources!C36/100 | E5: =Sources!C6*Sources!D36/100
A6: =Sources!B7 | B6: =Sources!C7 | C6: =Sources!C7*Sources!B37/100 | D6: =Sources!C7*Sources!C37/100 | E6: =Sources!C7*Sources!D37/100
A7: =Sources!B8 | B7: =Sources!C8 | C7: =Sources!C8*Sources!B38/100 | D7: =Sources!C8*Sources!C38/100 | E7: =Sources!C8*Sources!D38/100
A8: =Sources!B9 | B8: =Sources!C9 | C8: =Sources!C9*Sources!B39/100 | D8: =Sources!C9*Sources!C39/100 | E8: =Sources!C9*Sources!D39/100
A9: =Sources!B10 | B9: =Sources!C10 | C9: =Sources!C10*Sources!B40/100 | D9: =Sources!C10*Sources!C40/100 | E9: =Sources!C10*Sources!D40/100
A10: =Sources!B11 | B10: =Sources!C11 | C10: =Sources!C11*Sources!B41/100 | D10: =Sources!C11*Sources!C41/100 | E10: =Sources!C11*Sources!D41/100
A11: TOTAL 2022-2023 (L) | C11: =SUM(C5:C10) | D11: =SUM(D5:D10) | E11: =SUM(E5:E10)
A13: 2. Assiette 2024-2025 (quantités de l'annexe finale du service) — nos doses
A14: Article | B14: Qté 2024-25 | C14: Nos doses (L)
A15: =Sources!B16 | B15: =Sources!C16 | C15: =Sources!C16*Sources!D39/100
A16: =Sources!B17 | B16: =Sources!C17 | C16: =Sources!C17*Sources!D38/100
A17: =Sources!B18 | B17: =Sources!C18 | C17: =Sources!C18*Sources!D41/100
A18: =Sources!B19 | B18: =Sources!C19 | C18: =Sources!C19*Sources!D40/100
A19: =Sources!B20 | B19: =Sources!C20 | C19: =Sources!C20*Sources!D36/100
A20: =Sources!B21 | B20: =Sources!C21 | C20: =Sources!C21*Sources!D37/100
A21: TOTAL 2024-2025 (L) | C21: =SUM(C15:C20)
A23: 3. Assiette 2023-2024 — nos doses (C2 ABSENT : résultat à étayer)
A24: Article | B24: Qté (à étayer) | C24: Nos doses (L)
A25: =Sources!B27 | B25: =Sources!C27 | C25: =Sources!C27*Sources!D36/100
A26: =Sources!B28 | B26: =Sources!C28 | C26: =Sources!C28*Sources!D37/100
A27: =Sources!B29 | B27: =Sources!C29 | C27: =Sources!C29*Sources!D38/100
A28: =Sources!B30 | B28: =Sources!C30 | C28: =Sources!C30*Sources!D39/100
A29: =Sources!B31 | B29: =Sources!C31 | C29: =Sources!C31*Sources!D40/100
A30: =Sources!B32 | B30: =Sources!C32 | C30: =Sources!C32*Sources!D41/100
A31: TOTAL 2023-2024 (L) | C31: =SUM(C25:C30)
A33: 4. Assiette totale retenue (nos doses, Monaco vendu INCLUS) et freinte illustrative
A34: Grandeur | B34: Valeur | C34: Formule / source
A35: Assiette 2022-2023 (L) | B35: =E11 | C35: primaire C1
A36: Assiette 2023-2024 (L) | B36: =C31 | C36: à étayer (C2 absent)
A37: Assiette 2024-2025 (L) | B37: =C21 | C37: annexe finale service
A38: ASSIETTE TOTALE 3 exercices (L) | B38: =B35+B36+B37 | C38: somme des trois lectures « nos doses »
A39: Freinte illustrative = taux × assiette (L) | B39: =B38*Sources!B56 | C39: 10 % — ESTIMÉ, non mesuré sur l'établissement
A40: dont RÉSIDU de fin de fût (seul poste chiffré par le constructeur, L) | B40: =Sources!B48*Sources!B52 | C40: 262 fûts × 0,12 L — DOCUMENTÉ
A41: Résidu en % de l'assiette | B41: =B40/B38 | C41: part de la freinte réellement documentée
A42: Résidu en % des litres achetés (2 096 L) | B42: =B40/Sources!C48
A44: 5. PIVOT CORRIGÉ : le 1er abattement du service porte sur le volume DISPONIBLE, non sur les achats
A45: Grandeur (2024-2025, seul exercice documenté) | B45: Valeur | C45: Formule / source
...

Sheet Méthode
A1: MÉTHODE — d'où vient chaque chiffre, étape par étape
A3: Objet. Le grief O « Perte de bières » porte sur la part du fût réputée vendue. Cette pièce reconstruit l'assiette de la bière réellement sortie du fût, la freinte, et le premier abattement du service, à partir des seules pièces du dossier.
A5: 1. Assiette 2022-2023 (Sources table A ; Calcul bloc 1). SOURCE PRIMAIRE : ANNEXE-C1, agrégée par référence. Six articles sortent du fût : pression 901,5 ; pinte 282,5 ; panaché 147 ; Picon bière 129 ; Pinte Picon 37 ; Monaco 66,5. Le Monaco 2022-2023 est à 66,5 unités — et NON à 0 : il a été vendu et sa part bière est sortie du fût. La pièce R1 l'avait mis à 0 (classement de l'annexe D1 hors section « Bières ») ; nous le réintégrons.
A7: 2. Assiette 2024-2025 (table B ; bloc 2). SOURCE SECONDAIRE : l'annexe finale du service (bloc « i)-INGREDIENT : BIERE »), qui porte 662 pression, 308 pinte, 97 panaché, 124 Picon bière, 59 Pinte Picon, 74 Monaco, total 39 151 cl. Quantités corroborées par la pièce du service, sans recourir à C3.
A9: 3. Assiette 2023-2024 (table C ; bloc 3). LIMITE : l'annexe C2 est ABSENTE. Les quantités sont reprises de R1, NON vérifiables sur source primaire ni sur l'annexe finale de cet exercice. Signalées « à étayer » (fond orangé) ; le résultat ne doit pas être présenté comme démontré.
A11: 4. Doses (table D). Service : proposition p. 50. Défense : part bière effective (panaché/Monaco 12,5 ; Picon 21/42). Nos doses jouent CONTRE la société (assiette plus basse), ce qui rend l'assiette prudente.
A13: 5. Freinte (bloc 4). ESTIMÉE à 10 % de l'assiette — borne basse de la fourchette technique (5 %–20 %). Ce 10 % N'EST PAS mesuré sur l'établissement. Le SEUL poste réellement chiffré par le constructeur est le résidu de fin de fût : 262 fûts × 120 ml = 31,44 L (manuel Blade ch. 6.3). Sur ~121 L de freinte illustrative, 31,4 L sont documentés, le solde est estimé.
A15: 6. Premier abattement du service (bloc 5). CORRECTION D'ASSIETTE. Le service applique son 15 % au volume DISPONIBLE (achats corrigés des stocks), non aux achats. L'annexe finale 2024-2025 le montre : 63 200 cl − 15 % = 53 720 cl nets. Donc 15 % × 632 L = 94,8 L, et NON 100,8 L (15 % des 672 L achetés). Pour 2022-2023 et 2023-2024, le disponible exige les annexes 6-1/6-2, absentes : le total « 314,4 L » n'est pas certifiable et n'est plus avancé comme tel.
A17: 7. Réconciliation 79 vs 84 fûts (2024-2025). Les factures FCBS portent 84 fûts ACHETÉS ; l'annexe finale porte 79 fûts DISPONIBLES (63 200 cl). L'écart de 5 fûts (40 L) est une variation de stock : le disponible commande l'assiette du 15 % du service.
A19: 8. Composition 27,75 % (bloc 6). Deux abattements de 15 % ne s'additionnent pas : 1 − 0,85 × 0,85 = 27,75 %, non 30 %. Base-indépendant.
A21: 9. Euros et dégrèvement (bloc 7). CA liquides bière 2024-2025 = 7 180,52 € pour 53 720 cl nets (0,13367 €/cl). Un point de freinte sur le disponible = 632 cl = 84,5 € de CA liquides, ~294,4 € de CA total. CONCLUSION : notre freinte 2024-2025 (39,2 L) est INFÉRIEURE au premier abattement du service (94,8 L). Le dégrèvement demandé au titre de la freinte est de 0 € : le service abat déjà davantage. Cette pièce sert la cohérence du bilan matière et la réfutation du motif (« 30 % »), non une réduction en euros.
A23: Vérification. Toutes les cellules de résultat de l'onglet Calcul sont des formules renvoyant à l'onglet Sources (aucun résultat en dur). Recalcul vérifié sous LibreOffice.
