Workbook

Sheet Sources
A1: La Demi-Lune — Bilan matiere produit par produit (partie I : consommation vendue superieure aux achats, p. 48 a 53)
A2: Donnees brutes. Achats = factures fournisseur Franche-Comte Boissons Services (199 factures), nets des avoirs. Conso = consommation mesuree caisse + cuisine. Inventaire = variation de stock (inventaires physiques 31/03/2023, 2024, 2025). Le Calvados est repris a sa consommation ITEMISEE de l'onglet Calvados (110,7 L : 1,44 verre + 109,26 cuisine a 4 cl), et non a la valeur 120,5 L de la feuille R1 (ecart de 9,8 L non reconcilie, corrige ici).
A4: Famille | B4: Produit | C4: Achats factures (L) | D4: Conso caisse + cuisine (L) | E4: Inventaire / var. stock (L) | F4: Reference d'achat de rattachement (bouton de caisse <> libelle facture)
A5: Bieres | B5: Fût Affligem | C5: 2096 | D5: 1501 | E5: 40
A6: Vins tranquilles | B6: Côtes de Provence rosé maison (Cap des Pins) | C6: 681 | D6: 286.8 | E6: 0
A7: Vins de liqueur (Macvin) | B7: Macvin | C7: 806.2 | D7: 470.8 | E7: 0
A8: Cremant et champagne | B8: Crémant du Jura | C8: 675 | D8: 379.6 | E8: 6.8
A9: Vins tranquilles | B9: Bourgogne Aligoté maison | C9: 630 | D9: 346.8 | E9: 0
A10: Vins tranquilles | B10: Saint Véran | C10: 465 | D10: 245.4 | E10: 5.2
A11: Vins tranquilles | B11: Rosé Les Jamelles (Clair de Rosé) | C11: 302.2 | D11: 97.9 | E11: 12
A12: Vins tranquilles | B12: Côtes du Rhône rouge maison (Chusclan) | C12: 360 | D12: 190.8 | E12: 0
A13: Vins tranquilles | B13: Arbois Chardonnay | C13: 201.7 | D13: 32.6 | E13: 12
A14: Cidres | B14: Cidre La Mordue | C14: 237.9 | D14: 92.5 | E14: 4.9
A15: Vins tranquilles | B15: Arbois Trousseau | C15: 462.7 | D15: 346.1 | E15: 6
A16: Vins tranquilles | B16: Moulin à Vent | C16: 201.8 | D16: 103.8 | E16: 7.5
... A32: Cidres | B32: Cidre Doux | C32: 126 | D32: 107.6 | E32: 0
A33: Vins tranquilles | B33: Hautes Côtes de Nuits blanc | C33: 18 | D33: 2.2 | E33: 0 | F33: 24 bt Lupe Cholet facturees (bilan 18 L)
A34: Cremant et champagne | B34: Champagne | C34: 29.2 | D34: 5.2 | E34: 9.8
A35: Liqueurs | B35: Liqueur de Sapin | C35: 17.2 | D35: 3.2 | E35: 0
A36: Vins tranquilles | B36: Rosé Le Pive | C36: 49.4 | D36: 26.2 | E36: 10.5
A37: Liqueurs | B37: Liqueur de Poire | C37: 16.8 | D37: 5.4 | E37: 0
A38: Vins tranquilles | B38: Vin de Paille | C38: 36.4 | D38: 24.9 | E38: 3
A39: Vins tranquilles | B39: Grand Pavois | C39: 18 | D39: 9.8 | E39: 0
A40: Liqueurs | B40: Get 27 | C40: 12 | D40: 3.3 | E40: 0.7
A41: Liqueurs | B41: Génépi | C41: 9.8 | D41: 2.3 | E41: 0.7
A42: Vins tranquilles | B42: Côtes de Provence Rosé Minuty | C42: 21 | D42: 11.2 | E42: 3.8
A43: Liqueurs | B43: Bailey's | C43: 22.4 | D43: 16.6 | E43: 0.7
A44: Liqueurs | B44: Passoa | C44: 15.4 | D44: 10.1 | E44: 1.4
A45: Eaux-de-vie et digestifs | B45: Eau de Vie Mirabelle | C45: 5.6 | D45: 1.1 | E45: 0.7
... A54: Aperitifs | B54: Pastis 51 | C54: 6 | D54: 4.3 | E54: 1
A55: Aperitifs | B55: Martini Blanc | C55: 13 | D55: 12.6 | E55: 1 | F55: conso<achats : deficit d'inventaire
A56: Liqueurs | B56: Grand Marnier | C56: 8.4 | D56: 8.1 | E56: 1.4 | F56: conso<achats : deficit d'inventaire
A57: Liqueurs | B57: Guignolet | C57: 0 | D57: 0 | E57: 1.4 | F57: conso=0 : deficit d'inventaire seul
A58: Eaux-de-vie et digestifs | B58: Eau de Vie Framboise | C58: 0 | D58: 0.8 | E58: 0.7 | F58: bouton; achats sous Mirabelle/EdV
A59: Liqueurs | B59: Get 31 | C59: 0 | D59: 0.9 | E59: 0.7 | F59: bouton; achats sous Get 27
A60: Eaux-de-vie et digestifs | B60: Marc du Jura | C60: 0 | D60: 2.4 | E60: 0 | F60: bouton; achats sous Marc de Bourgogne
A61: Eaux-de-vie et digestifs | B61: Eau de Vie de Poire | C61: 0 | D61: 1.7 | E61: 0.7 | F61: bouton; achats sous Liqueur de Poire
A62: Vins tranquilles | B62: Hautes Côtes de Beaune blanc | C62: 0 | D62: 4.5 | E62: 0 | F62: servi sur stock HC Nuits blanc (cf. ventes-sans-achat)
A63: Liqueurs | B63: Liqueur de Cerise | C63: 12.7 | D63: 16.1 | E63: 1.4 | F63: bouton; proche Guignolet (cerise)
A64: Vins tranquilles | B64: Miraval Rosé | C64: 0 | D64: 6 | E64: 0 | F64: bouton rose; achats sous les autres roses
...

Sheet Calvados
A1: Calvados : consommation itemisee par libelle de caisse x dose declaree de 4 cl (3 exercices)
A2: Dose SERVIE = verre de digestif, enregistre et facture en caisse (recette de boisson). Dose EN CUISINE = flambage/rotissage, charge de matiere d'un plat deja facture. Volume = quantite x 4 cl. Total = la consommation Calvados retenue au bilan (valeur verifiee, itemisee).
A4: Usage | B4: Libelle de caisse | C4: Quantite (3 ex.) | D4: Dose (cl) | E4: Volume (L)
A5: Dose servie (verre) | B5: Calvados (4cl) | C5: 32 | D5: 4 | E5: =C5*D5/100
A6: Dose servie (verre) | B6: Calvados | C6: 4 | D6: 4 | E6: =C6*D6/100
A7: Dose cuisine | B7: CAMEMBERT ROTI | C7: 1451.6 | D7: 4 | E7: =C7*D7/100
A8: Dose cuisine | B8: ASSIETTE PERE GREGOIRE | C8: 648 | D8: 4 | E8: =C8*D8/100
A9: Dose cuisine | B9: GALETTE FRELEE | C9: 346 | D9: 4 | E9: =C9*D9/100
A10: Dose cuisine | B10: CREPE FLAMBEE | C10: 113 | D10: 4 | E10: =C10*D10/100
A11: Dose cuisine | B11: DESSERT BASILIC | C11: 83 | D11: 4 | E11: =C11*D11/100
A12: Dose cuisine | B12: DESSERT GRAPPINS | C12: 67 | D12: 4 | E12: =C12*D12/100
A13: Dose cuisine | B13: DESSERT FLAMBEE | C13: 23 | D13: 4 | E13: =C13*D13/100
B14: TOTAL consommation Calvados (verre + cuisine) | E14: =SUM(E5:E13)
B15: dont verre (recette de boisson) | E15: =SUM(E5:E6)
B16: dont cuisine (charge de matiere) | E16: =SUM(E7:E13)
B17: Achats factures (73 bt de 1 L, 1 227,74 EUR HT) | E17: 73
B18: Variation d'inventaire (stock 1 bt a l'ouverture et a la cloture) | E18: 1
B19: Bilan net Calvados = achats - conso - inventaire | E19: =E17-E14-E18
B20: Deficit conso - achats = conso - achats | E20: =E14-E17

Sheet Bilan produit
A1: Bilan matiere, produit par produit : net et sens de l'ecart, PAR FORMULE
A2: Bilan net = achats - conso - inventaire. Deficit conso-achats = conso - achats (>0 = consommation superieure aux achats). Les lignes importees de l'onglet Sources ; aucun resultat n'est tape en dur.
A4: Famille | B4: Produit | C4: Achats (L) | D4: Conso (L) | E4: Inv (L) | F4: Bilan net (L) | G4: Conso - achats (L)
A5: =Sources!A5 | B5: =Sources!B5 | C5: =Sources!C5 | D5: =Sources!D5 | E5: =Sources!E5 | F5: =C5-D5-E5 | G5: =D5-C5
A6: =Sources!A6 | B6: =Sources!B6 | C6: =Sources!C6 | D6: =Sources!D6 | E6: =Sources!E6 | F6: =C6-D6-E6 | G6: =D6-C6
A7: =Sources!A7 | B7: =Sources!B7 | C7: =Sources!C7 | D7: =Sources!D7 | E7: =Sources!E7 | F7: =C7-D7-E7 | G7: =D7-C7
A8: =Sources!A8 | B8: =Sources!B8 | C8: =Sources!C8 | D8: =Sources!D8 | E8: =Sources!E8 | F8: =C8-D8-E8 | G8: =D8-C8
A9: =Sources!A9 | B9: =Sources!B9 | C9: =Sources!C9 | D9: =Sources!D9 | E9: =Sources!E9 | F9: =C9-D9-E9 | G9: =D9-C9
A10: =Sources!A10 | B10: =Sources!B10 | C10: =Sources!C10 | D10: =Sources!D10 | E10: =Sources!E10 | F10: =C10-D10-E10 | G10: =D10-C10
A11: =Sources!A11 | B11: =Sources!B11 | C11: =Sources!C11 | D11: =Sources!D11 | E11: =Sources!E11 | F11: =C11-D11-E11 | G11: =D11-C11
A12: =Sources!A12 | B12: =Sources!B12 | C12: =Sources!C12 | D12: =Sources!D12 | E12: =Sources!E12 | F12: =C12-D12-E12 | G12: =D12-C12
A13: =Sources!A13 | B13: =Sources!B13 | C13: =Sources!C13 | D13: =Sources!D13 | E13: =Sources!E13 | F13: =C13-D13-E13 | G13: =D13-C13
A14: =Sources!A14 | B14: =Sources!B14 | C14: =Sources!C14 | D14: =Sources!D14 | E14: =Sources!E14 | F14: =C14-D14-E14 | G14: =D14-C14
A15: =Sources!A15 | B15: =Sources!B15 | C15: =Sources!C15 | D15: =Sources!D15 | E15: =Sources!E15 | F15: =C15-D15-E15 | G15: =D15-C15
A16: =Sources!A16 | B16: =Sources!B16 | C16: =Sources!C16 | D16: =Sources!D16 | E16: =Sources!E16 | F16: =C16-D16-E16 | G16: =D16-C16
... A69: =Sources!A69 | B69: =Sources!B69 | C69: =Sources!C69 | D69: =Sources!D69 | E69: =Sources!E69 | F69: =C69-D69-E69 | G69: =D69-C69
B70: TOTAL 65 produits | C70: =SUM(C5:C69) | D70: =SUM(D5:D69) | E70: =SUM(E5:E69) | F70: =SUM(F5:F69) | G70: =SUM(G5:G69)

Sheet Bilan famille
A1: Bilan matiere par famille (SOMME.SI sur l'onglet Bilan produit), PAR FORMULE
A3: Famille | B3: Achats (L) | C3: Conso (L) | D3: Inv (L) | E3: Bilan net (L) | F3: Bilan / achats
A4: Vins tranquilles | B4: =SUMIF('Bilan produit'!$A$5:$A$69,A4,'Bilan produit'!$C$5:$C$69) | C4: =SUMIF('Bilan produit'!$A$5:$A$69,A4,'Bilan produit'!$D$5:$D$69) | D4: =SUMIF('Bilan produit'!$A$5:$A$69,A4,'Bilan produit'!$E$5:$E$69) | E4: =B4-C4-D4 | F4: =E4/B4
A5: Bieres | B5: =SUMIF('Bilan produit'!$A$5:$A$69,A5,'Bilan produit'!$C$5:$C$69) | C5: =SUMIF('Bilan produit'!$A$5:$A$69,A5,'Bilan produit'!$D$5:$D$69) | D5: =SUMIF('Bilan produit'!$A$5:$A$69,A5,'Bilan produit'!$E$5:$E$69) | E5: =B5-C5-D5 | F5: =E5/B5
A6: Vins de liqueur (Macvin) | B6: =SUMIF('Bilan produit'!$A$5:$A$69,A6,'Bilan produit'!$C$5:$C$69) | C6: =SUMIF('Bilan produit'!$A$5:$A$69,A6,'Bilan produit'!$D$5:$D$69) | D6: =SUMIF('Bilan produit'!$A$5:$A$69,A6,'Bilan produit'!$E$5:$E$69) | E6: =B6-C6-D6 | F6: =E6/B6
A7: Cremant et champagne | B7: =SUMIF('Bilan produit'!$A$5:$A$69,A7,'Bilan produit'!$C$5:$C$69) | C7: =SUMIF('Bilan produit'!$A$5:$A$69,A7,'Bilan produit'!$D$5:$D$69) | D7: =SUMIF('Bilan produit'!$A$5:$A$69,A7,'Bilan produit'!$E$5:$E$69) | E7: =B7-C7-D7 | F7: =E7/B7
A8: Cidres | B8: =SUMIF('Bilan produit'!$A$5:$A$69,A8,'Bilan produit'!$C$5:$C$69) | C8: =SUMIF('Bilan produit'!$A$5:$A$69,A8,'Bilan produit'!$D$5:$D$69) | D8: =SUMIF('Bilan produit'!$A$5:$A$69,A8,'Bilan produit'!$E$5:$E$69) | E8: =B8-C8-D8 | F8: =E8/B8
A9: Liqueurs | B9: =SUMIF('Bilan produit'!$A$5:$A$69,A9,'Bilan produit'!$C$5:$C$69) | C9: =SUMIF('Bilan produit'!$A$5:$A$69,A9,'Bilan produit'!$D$5:$D$69) | D9: =SUMIF('Bilan produit'!$A$5:$A$69,A9,'Bilan produit'!$E$5:$E$69) | E9: =B9-C9-D9 | F9: =E9/B9
A10: Aperitifs | B10: =SUMIF('Bilan produit'!$A$5:$A$69,A10,'Bilan produit'!$C$5:$C$69) | C10: =SUMIF('Bilan produit'!$A$5:$A$69,A10,'Bilan produit'!$D$5:$D$69) | D10: =SUMIF('Bilan produit'!$A$5:$A$69,A10,'Bilan produit'!$E$5:$E$69) | E10: =B10-C10-D10 | F10: =E10/B10
A11: Spiritueux | B11: =SUMIF('Bilan produit'!$A$5:$A$69,A11,'Bilan produit'!$C$5:$C$69) | C11: =SUMIF('Bilan produit'!$A$5:$A$69,A11,'Bilan produit'!$D$5:$D$69) | D11: =SUMIF('Bilan produit'!$A$5:$A$69,A11,'Bilan produit'!$E$5:$E$69) | E11: =B11-C11-D11 | F11: =E11/B11
A12: Eaux-de-vie et digestifs | B12: =SUMIF('Bilan produit'!$A$5:$A$69,A12,'Bilan produit'!$C$5:$C$69) | C12: =SUMIF('Bilan produit'!$A$5:$A$69,A12,'Bilan produit'!$D$5:$D$69) | D12: =SUMIF('Bilan produit'!$A$5:$A$69,A12,'Bilan produit'!$E$5:$E$69) | E12: =B12-C12-D12 | F12: =E12/B12
A13: TOTAL | B13: =SUM(B4:B12) | C13: =SUM(C4:C12) | D13: =SUM(D4:D12) | E13: =SUM(E4:E12) | F13: =E13/B13
A15: Eaux-de-vie HORS Calvados (achats-conso-inv) | B15: =B12-Calvados!E17 | E15: =E12-Calvados!E19

Sheet Achats non rattaches
A1: Trois libelles sous-evalues a l'achat dans le bilan R1 (millesimes / demi-bouteilles factures sous designations distinctes)
A2: Ces achats factures Franche-Comte Boissons Services existent mais n'ont pas ete rattaches au produit au bilan R1. Les reprendre ne fait qu'augmenter l'excedent : le bilan est un plancher.
A4: Produit | B4: Volume lu sur factures (L) | C4: Volume retenu au bilan R1 (L) | D4: Ecart non rattache (L) | E4: Conso (L) : conso < achats reels ?
A5: Chablis | B5: 104.2 | C5: 18 | D5: =B5-C5 | E5: =B5-73.7
A6: Gewurztraminer | B6: 102 | C6: 6 | D6: =B6-C6 | E6: =B6-78.9
A7: Arbois Béthanie | B7: 385.5 | C7: 214.5 | D7: =B7-C7 | E7: =B7-309.9
A8: TOTAL | B8: =SUM(B5:B7) | C8: =SUM(C5:C7) | D8: =SUM(D5:D7)

Sheet Produits deficitaires
A1: Les 15 produits en deficit de bilan net : traitement honnete, un par un
A2: Importes de l'onglet Bilan produit (net < 0). Colonne 'Conso - achats' : >0 = veritable consommation superieure aux achats ; <=0 = deficit du a la seule variation d'inventaire (pas une conso sans achat).
A4: Produit | B4: Achats (L) | C4: Conso (L) | D4: Bilan net (L) | E4: Conso - achats (L) | F4: Nature | G4: Traitement
A5: ='Bilan produit'!B69 | B5: ='Bilan produit'!C69 | C5: ='Bilan produit'!D69 | D5: ='Bilan produit'!F69 | E5: ='Bilan produit'!G69 | F5: conso>achats | G5: Regroupement : bouton pichet/BIB ; achats sous les vins maison en BIB (roses/Aligote/Chusclan maison), tous tres excedentaires. Meme traitement que Mouton Cadet (ventes-sans-achat).
A6: ='Bilan produit'!B68 | B6: ='Bilan produit'!C68 | C6: ='Bilan produit'!D68 | D6: ='Bilan produit'!F68 | E6: ='Bilan produit'!G68 | F6: conso>achats | G6: Plancher : 385,5 L factures (demi-bt 37,5 cl sous libelle distinct) contre 214,5 retenus ; achats reels 385,5 > conso 309,9 -> +75,6 L.
A7: ='Bilan produit'!B67 | B7: ='Bilan produit'!C67 | C7: ='Bilan produit'!D67 | D7: ='Bilan produit'!F67 | E7: ='Bilan produit'!G67 | F7: conso>achats | G7: Plancher : 102,0 L factures (millesimes distincts) contre 6,0 retenus ; 102,0 > conso 78,9 -> +23,1 L.
A8: ='Bilan produit'!B66 | B8: ='Bilan produit'!C66 | C8: ='Bilan produit'!D66 | D8: ='Bilan produit'!F66 | E8: ='Bilan produit'!G66 | F8: conso>achats | G8: Plancher : 104,2 L factures contre 18,0 retenus ; 104,2 > conso 73,7 -> +30,5 L.
A9: ='Bilan produit'!B65 | B9: ='Bilan produit'!C65 | C9: ='Bilan produit'!D65 | D9: ='Bilan produit'!F65 | E9: ='Bilan produit'!G65 | F9: conso>achats | G9: IRREDUCTIBLE par le calcul : dose de cuisine (flambage) surestimee ; charge de matiere d'un plat facture, pas une recette de boisson (cf. 2.5 a 2.9). Seul point non clos par piece.
A10: ='Bilan produit'!B64 | B10: ='Bilan produit'!C64 | C10: ='Bilan produit'!D64 | D10: ='Bilan produit'!F64 | E10: ='Bilan produit'!G64 | F10: conso>achats | G10: Regroupement : bouton rose ; achats sous les autres roses (Jamelles +192,3, Le Pive, Minuty, Boheme), excedentaires.
A11: ='Bilan produit'!B63 | B11: ='Bilan produit'!C63 | C11: ='Bilan produit'!D63 | D11: ='Bilan produit'!F63 | E11: ='Bilan produit'!G63 | F11: conso>achats | G11: Regroupement/concession liqueurs (famille +132,5 L) ; proche du Guignolet (liqueur de cerise).
A12: ='Bilan produit'!B62 | B12: ='Bilan produit'!C62 | C12: ='Bilan produit'!D62 | D12: ='Bilan produit'!F62 | E12: ='Bilan produit'!G62 | F12: conso>achats | G12: Regroupement : servi sur le stock de HC de Nuits blanc (meme traitement que ventes-sans-achat).
A13: ='Bilan produit'!B60 | B13: ='Bilan produit'!C60 | C13: ='Bilan produit'!D60 | D13: ='Bilan produit'!F60 | E13: ='Bilan produit'!G60 | F13: conso>achats | G13: Regroupement eaux-de-vie : achats sous Marc de Bourgogne (+3,3 L).
A14: ='Bilan produit'!B61 | B14: ='Bilan produit'!C61 | C14: ='Bilan produit'!D61 | D14: ='Bilan produit'!F61 | E14: ='Bilan produit'!G61 | F14: conso>achats | G14: Regroupement : achats sous Liqueur de Poire (+11,4 L) et Mirabelle.
A15: ='Bilan produit'!B59 | B15: ='Bilan produit'!C59 | C15: ='Bilan produit'!D59 | D15: ='Bilan produit'!F59 | E15: ='Bilan produit'!G59 | F15: conso>achats | G15: Regroupement : achats sous Get 27 (+8,0 L).
A16: ='Bilan produit'!B58 | B16: ='Bilan produit'!C58 | C16: ='Bilan produit'!D58 | D16: ='Bilan produit'!F58 | E16: ='Bilan produit'!G58 | F16: conso>achats | G16: Regroupement : achats sous Mirabelle (+3,8 L).
A17: ='Bilan produit'!B57 | B17: ='Bilan produit'!C57 | C17: ='Bilan produit'!D57 | D17: ='Bilan produit'!F57 | E17: ='Bilan produit'!G57 | F17: inventaire seul | G17: Deficit d'inventaire pur (conso 0) : AUCUNE consommation sans achat.
A18: ='Bilan produit'!B56 | B18: ='Bilan produit'!C56 | C18: ='Bilan produit'!D56 | D18: ='Bilan produit'!F56 | E18: ='Bilan produit'!G56 | F18: inventaire | G18: Conso 8,1 < achats 8,4 : le deficit (-1,1) tient a la seule variation d'inventaire.
A19: ='Bilan produit'!B55 | B19: ='Bilan produit'!C55 | C19: ='Bilan produit'!D55 | D19: ='Bilan produit'!F55 | E19: ='Bilan produit'!G55 | F19: inventaire | G19: Conso 12,6 < achats 13,0 : deficit d'inventaire / frontiere d'exercice (deja traite en 2.1).
A20: TOTAL 15 deficits | D20: =SUM(D5:D19) | E20: =SUM(E5:E19)

Sheet Methode
A1: Methode — d'ou vient chaque chiffre
A3: 1. Sources : les 65 produits de boisson, avec achats factures (199 factures Franche-Comte Boissons Services, nets d'avoirs), consommation mesuree (caisse + cuisine) et variation d'inventaire (inventaires physiques 31/03/2023, 2024, 2025). Donnees brutes, aucune formule.
A5: 2. Calvados : la consommation est itemisee par libelle de caisse x dose declaree de 4 cl. Volume (L) = quantite x 4 / 100, par formule. Total = 110,7 L (1,44 L au verre, enregistre et facture ; 109,26 L en cuisine, charge de matiere). C'est la valeur retenue au bilan, verifiee ligne a ligne. La feuille R1 'Bilan matiere produit' portait 120,5 L (ecart de 9,8 L non reconcilie) : la correction augmente l'excedent global, elle ne le reduit pas.
A7: 3. Bilan produit : pour chaque produit, bilan net = achats - conso - inventaire (formule), et deficit conso-achats = conso - achats (formule). Aucun resultat tape en dur.
A9: 4. Bilan famille : SOMME.SI par famille sur l'onglet Bilan produit, puis bilan net et bilan/achats par formule. Total general par SOMME.
A11: 5. Produits deficitaires : les 15 produits a bilan net < 0, importes par formule de l'onglet Bilan produit, avec la nature du deficit (conso>achats vs inventaire seul) et le traitement (regroupement legitime, plancher d'achats, ou point irreductible du Calvados).
A13: 6. Achats non rattaches : Chablis, Gewurztraminer, Arbois Bethanie sont sous-evalues a l'achat au bilan R1 (millesimes/demi-bouteilles factures sous designations distinctes). Volume facture reel contre volume retenu, par formule : le bilan est un plancher.
A15: IMPORTANT : ce classeur ne calcule AUCUNE 'dose d'equilibre' par retro-calcul du bilan. La dose reellement mise en cuisine releve de la recette de l'etablissement et sera precisee par declaration de la gerance, non par une division (cf. page, 2.7).
A17: Sens de l'ecart (titre de la partie I) : sur les 65 produits, 12 presentent conso > achats (718,1 L cumules, dont Cubis 426,9 L et Calvados). 11 des 12 se rattachent a un regroupement legitime ou a un plancher d'achats ; seul le Calvados (dose de cuisine) reste discute au fond. 3 des 15 deficits (Guignolet, Grand Marnier, Martini) tiennent a la seule variation d'inventaire : ce ne sont pas des consommations sans achat.
