Workbook

Sheet Lignes C
A1: Exercice | B1: Date | C1: N° note (jour) | D1: Id note (unique) | E1: Article | F1: PU (€) | G1: Qté | H1: Encaissé (col. 17 annexe C) (€) | I1: Col. C du service « Prix TTC × Qté virgule neutralisée » (€) | J1: Col. D du service « Écart C − 17 » (€) | K1: Statut (recomposition R2) | L1: Table (notes jumelles) | M1: Recalcul : PU × entier supérieur (€) | N1: Recalcul : écart = M − H (€) | O1: Col. D = recalcul ? (1/0)
A2: 2022-2023 | B2: 2022-04-14 | C2: 11 | D2: 46637 | E2: BARBEULENET | F2: 13.9 | G2: 0.5 | H2: 6.95 | I2: 13.9 | J2: 6.95 | K2: refermé (somme entière) | L2: n° 11 + n° 12 | M2: =CEILING(G2,1)*F2 -> 13.9 | N2: =M2-H2 -> 6.95 | O2: =IF(ABS(N2-J2)<0.011,1,0) -> 1
A3: 2022-2023 | B3: 2022-04-14 | C3: 11 | D3: 46637 | E3: Croûtes Morilles | F3: 16.9 | G3: 0.5 | H3: 8.45 | I3: 16.9 | J3: 8.45 | K3: refermé (somme entière) | L3: n° 11 + n° 12 | M3: =CEILING(G3,1)*F3 -> 16.9 | N3: =M3-H3 -> 8.45 | O3: =IF(ABS(N3-J3)<0.011,1,0) -> 1
A4: 2022-2023 | B4: 2022-04-14 | C4: 11 | D4: 46637 | E4: Père Gregoire | F4: 4.9 | G4: 0.5 | H4: 2.45 | I4: 4.9 | J4: 2.45 | K4: refermé (somme entière) | L4: n° 11 + n° 12 | M4: =CEILING(G4,1)*F4 -> 4.9 | N4: =M4-H4 -> 2.45 | O4: =IF(ABS(N4-J4)<0.011,1,0) -> 1
A5: 2022-2023 | B5: 2022-04-14 | C5: 11 | D5: 46637 | E5: SAUCE CHOCO/CAFE/CAR | F5: 1.8 | G5: 0.5 | H5: 0.9 | I5: 1.8 | J5: 0.9 | K5: refermé (somme entière) | L5: n° 11 + n° 12 | M5: =CEILING(G5,1)*F5 -> 1.8 | N5: =M5-H5 -> 0.9 | O5: =IF(ABS(N5-J5)<0.011,1,0) -> 1
A6: 2022-2023 | B6: 2022-04-14 | C6: 11 | D6: 46637 | E6: Salade Verte aux Noi | F6: 5.9 | G6: 0.5 | H6: 2.95 | I6: 5.9 | J6: 2.95 | K6: refermé (somme entière) | L6: n° 11 + n° 12 | M6: =CEILING(G6,1)*F6 -> 5.9 | N6: =M6-H6 -> 2.95 | O6: =IF(ABS(N6-J6)<0.011,1,0) -> 1
A7: 2022-2023 | B7: 2022-04-14 | C7: 11 | D7: 46637 | E7: pression | F7: 3.9 | G7: 0.5 | H7: 1.95 | I7: 3.9 | J7: 1.95 | K7: refermé (somme entière) | L7: n° 11 + n° 12 | M7: =CEILING(G7,1)*F7 -> 3.9 | N7: =M7-H7 -> 1.95 | O7: =IF(ABS(N7-J7)<0.011,1,0) -> 1
A8: 2022-2023 | B8: 2022-04-14 | C8: 12 | D8: 46636 | E8: BARBEULENET | F8: 13.9 | G8: 0.5 | H8: 6.95 | I8: 13.9 | J8: 6.95 | K8: refermé (somme entière) | L8: n° 11 + n° 12 | M8: =CEILING(G8,1)*F8 -> 13.9 | N8: =M8-H8 -> 6.95 | O8: =IF(ABS(N8-J8)<0.011,1,0) -> 1
A9: 2022-2023 | B9: 2022-04-14 | C9: 12 | D9: 46636 | E9: Croûtes Morilles | F9: 16.9 | G9: 0.5 | H9: 8.45 | I9: 16.9 | J9: 8.45 | K9: refermé (somme entière) | L9: n° 11 + n° 12 | M9: =CEILING(G9,1)*F9 -> 16.9 | N9: =M9-H9 -> 8.45 | O9: =IF(ABS(N9-J9)<0.011,1,0) -> 1
A10: 2022-2023 | B10: 2022-04-14 | C10: 12 | D10: 46636 | E10: Père Gregoire | F10: 4.9 | G10: 0.5 | H10: 2.45 | I10: 4.9 | J10: 2.45 | K10: refermé (somme entière) | L10: n° 11 + n° 12 | M10: =CEILING(G10,1)*F10 -> 4.9 | N10: =M10-H10 -> 2.45 | O10: =IF(ABS(N10-J10)<0.011,1,0) -> 1
A11: 2022-2023 | B11: 2022-04-14 | C11: 12 | D11: 46636 | E11: SAUCE CHOCO/CAFE/CAR | F11: 1.8 | G11: 0.5 | H11: 0.9 | I11: 1.8 | J11: 0.9 | K11: refermé (somme entière) | L11: n° 11 + n° 12 | M11: =CEILING(G11,1)*F11 -> 1.8 | N11: =M11-H11 -> 0.9 | O11: =IF(ABS(N11-J11)<0.011,1,0) -> 1
A12: 2022-2023 | B12: 2022-04-14 | C12: 12 | D12: 46636 | E12: Salade Verte aux Noi | F12: 5.9 | G12: 0.5 | H12: 2.95 | I12: 5.9 | J12: 2.95 | K12: refermé (somme entière) | L12: n° 11 + n° 12 | M12: =CEILING(G12,1)*F12 -> 5.9 | N12: =M12-H12 -> 2.95 | O12: =IF(ABS(N12-J12)<0.011,1,0) -> 1
A13: 2022-2023 | B13: 2022-04-14 | C13: 12 | D13: 46636 | E13: pression | F13: 3.9 | G13: 0.5 | H13: 1.95 | I13: 3.9 | J13: 1.95 | K13: refermé (somme entière) | L13: n° 11 + n° 12 | M13: =CEILING(G13,1)*F13 -> 3.9 | N13: =M13-H13 -> 1.95 | O13: =IF(ABS(N13-J13)<0.011,1,0) -> 1
... A412: 2022-2023 | B412: 2022-05-25 | C412: 25 | D412: 47740 | E412: VERRE H.C.DE BEAUNE | F412: 7.9 | G412: 0.5 | H412: 3.95 | I412: 7.9 | J412: 3.95 | K412: refermé (somme entière) | L412: n° 24 + n° 25 | M412: =CEILING(G412,1)*F412 -> 7.9 | N412: =M412-H412 -> 3.95 | O412: =IF(ABS(N412-J412)<0.011,1,0) -> 1
A413: 2022-2023 | B413: 2022-05-25 | C413: 29 | D413: 47755 | E413: Escargots de Bourgog | F413: 8 | G413: 0.5 | H413: 4 | I413: 8 | J413: 4 | K413: note isolée (non rattachée) | M413: =CEILING(G413,1)*F413 -> 8 | N413: =M413-H413 -> 4 | O413: =IF(ABS(N413-J413)<0.011,1,0) -> 1
A414: 2022-2023 | B414: 2022-05-25 | C414: 29 | D414: 47755 | E414: Feuilleté Forestier | F414: 10.9 | G414: 0.5 | H414: 5.45 | I414: 10.9 | J414: 5.45 | K414: note isolée (non rattachée) | M414: =CEILING(G414,1)*F414 -> 10.9 | N414: =M414-H414 -> 5.45 | O414: =IF(ABS(N414-J414)<0.011,1,0) -> 1
A415: 2022-2023 | B415: 2022-05-26 | C415: 3 | D415: 47773 | E415: Coca (25cl) | F415: 3.9 | G415: 0.5 | H415: 1.95 | I415: 3.9 | J415: 1.95 | K415: refermé (somme entière) | L415: n° 3 + n° 4 | M415: =CEILING(G415,1)*F415 -> 3.9 | N415: =M415-H415 -> 1.95 | O415: =IF(ABS(N415-J415)<0.011,1,0) -> 1
A416: 2022-2023 | B416: 2022-05-26 | C416: 3 | D416: 47773 | E416: Déca | F416: 2.2 | G416: 0.5 | H416: 1.1 | I416: 2.2 | J416: 1.1 | K416: refermé (somme entière) | L416: n° 3 + n° 4 | M416: =CEILING(G416,1)*F416 -> 2.2 | N416: =M416-H416 -> 1.1 | O416: =IF(ABS(N416-J416)<0.011,1,0) -> 1
A417: 2022-2023 | B417: 2022-05-26 | C417: 3 | D417: 47773 | E417: Limonade (25cl) | F417: 3.9 | G417: 0.5 | H417: 1.95 | I417: 3.9 | J417: 1.95 | K417: refermé (somme entière) | L417: n° 3 + n° 4 | M417: =CEILING(G417,1)*F417 -> 3.9 | N417: =M417-H417 -> 1.95 | O417: =IF(ABS(N417-J417)<0.011,1,0) -> 1
A418: 2022-2023 | B418: 2022-05-26 | C418: 3 | D418: 47773 | E418: MORTEAU GRILLEE | F418: 17.6 | G418: 0.5 | H418: 8.8 | I418: 17.6 | J418: 8.8 | K418: refermé (somme entière) | L418: n° 3 + n° 4 | M418: =CEILING(G418,1)*F418 -> 17.6 | N418: =M418-H418 -> 8.8 | O418: =IF(ABS(N418-J418)<0.011,1,0) -> 1
A419: 2022-2023 | B419: 2022-05-26 | C419: 3 | D419: 47773 | E419: Menu Bambin | F419: 6.9 | G419: 0.5 | H419: 3.45 | I419: 6.9 | J419: 3.45 | K419: refermé (somme entière) | L419: n° 3 + n° 4 | M419: =CEILING(G419,1)*F419 -> 6.9 | N419: =M419-H419 -> 3.45 | O419: =IF(ABS(N419-J419)<0.011,1,0) -> 1
A420: 2022-2023 | B420: 2022-05-26 | C420: 3 | D420: 47773 | E420: TRUITE PESTO | F420: 15.9 | G420: 0.5 | H420: 7.95 | I420: 15.9 | J420: 7.95 | K420: refermé (somme entière) | L420: n° 3 + n° 4 | M420: =CEILING(G420,1)*F420 -> 15.9 | N420: =M420-H420 -> 7.95 | O420: =IF(ABS(N420-J420)<0.011,1,0) -> 1
A421: 2022-2023 | B421: 2022-05-26 | C421: 4 | D421: 47758 | E421: Coca (25cl) | F421: 3.9 | G421: 0.5 | H421: 1.95 | I421: 3.9 | J421: 1.95 | K421: refermé (somme entière) | L421: n° 3 + n° 4 | M421: =CEILING(G421,1)*F421 -> 3.9 | N421: =M421-H421 -> 1.95 | O421: =IF(ABS(N421-J421)<0.011,1,0) -> 1
A422: 2022-2023 | B422: 2022-05-26 | C422: 4 | D422: 47758 | E422: Déca | F422: 2.2 | G422: 0.5 | H422: 1.1 | I422: 2.2 | J422: 1.1 | K422: refermé (somme entière) | L422: n° 3 + n° 4 | M422: =CEILING(G422,1)*F422 -> 2.2 | N422: =M422-H422 -> 1.1 | O422: =IF(ABS(N422-J422)<0.011,1,0) -> 1
A423: 2022-2023 | B423: 2022-05-26 | C423: 4 | D423: 47758 | E423: Limonade (25cl) | F423: 3.9 | G423: 0.5 | H423: 1.95 | I423: 3.9 | J423: 1.95 | K423: refermé (somme entière) | L423: n° 3 + n° 4 | M423: =CEILING(G423,1)*F423 -> 3.9 | N423: =M423-H423 -> 1.95 | O423: =IF(ABS(N423-J423)<0.011,1,0) -> 1
A424: 2022-2023 | B424: 2022-05-26 | C424: 4 | D424: 47758 | E424: MORTEAU GRILLEE | F424: 17.6 | G424: 0.5 | H424: 8.8 | I424: 17.6 | J424: 8.8 | K424: refermé (somme entière) | L424: n° 3 + n° 4 | M424: =CEILING(G424,1)*F424 -> 17.6 | N424: =M424-H424 -> 8.8 | O424: =IF(ABS(N424-J424)<0.011,1,0) -> 1
A425: 2022-2023 | B425: 2022-05-26 | C425: 4 | D425: 47758 | E425: Menu Bambin | F425: 6.9 | G425: 0.5 | H425: 3.45 | I425: 6.9 | J425: 3.45 | K425: refermé (somme entière) | L425: n° 3 + n° 4 | M425: =CEILING(G425,1)*F425 -> 6.9 | N425: =M425-H425 -> 3.45 | O425: =IF(ABS(N425-J425)<0.011,1,0) -> 1
A426: 2022-2023 | B426: 2022-05-26 | C426: 4 | D426: 47758 | E426: TRUITE PESTO | F426: 15.9 | G426: 0.5 | H426: 7.95 | I426: 15.9 | J426: 7.95 | K426: refermé (somme entière) | L426: n° 3 + n° 4 | M426: =CEILING(G426,1)*F426 -> 15.9 | N426: =M426-H426 -> 7.95 | O426: =IF(ABS(N426-J426)<0.011,1,0) -> 1
... A526: 2022-2023 | B526: 2022-05-29 | C526: 32 | D526: 47929 | E526: TANTE ARIE | F526: 8.5 | G526: 0.5 | H526: 4.25 | I526: 8.5 | J526: 4.25 | K526: refermé (somme entière) | L526: n° 31 + n° 32 | M526: =CEILING(G526,1)*F526 -> 8.5 | N526: =M526-H526 -> 4.25 | O526: =IF(ABS(N526-J526)<0.011,1,0) -> 1
A527: 2022-2023 | B527: 2022-06-01 | C527: 5 | D527: 47946 | E527: ASSIETTE FRANC-COMTO | F527: 17.6 | G527: 0.5 | H527: 8.8 | I527: 17.6 | J527: 8.8 | K527: note isolée (non rattachée) | M527: =CEILING(G527,1)*F527 -> 17.6 | N527: =M527-H527 -> 8.8 | O527: =IF(ABS(N527-J527)<0.011,1,0) -> 1
A528: 2022-2023 | B528: 2022-06-01 | C528: 5 | D528: 47946 | E528: CAMEMBERT ROTI | F528: 17.6 | G528: 0.5 | H528: 8.8 | I528: 17.6 | J528: 8.8 | K528: note isolée (non rattachée) | M528: =CEILING(G528,1)*F528 -> 17.6 | N528: =M528-H528 -> 8.8 | O528: =IF(ABS(N528-J528)<0.011,1,0) -> 1
A529: 2022-2023 | B529: 2022-06-01 | C529: 5 | D529: 47946 | E529: Chat perché | F529: 5.2 | G529: 0.5 | H529: 2.6 | I529: 5.2 | J529: 2.6 | K529: note isolée (non rattachée) | M529: =CEILING(G529,1)*F529 -> 5.2 | N529: =M529-H529 -> 2.6 | O529: =IF(ABS(N529-J529)<0.011,1,0) -> 1
A530: 2022-2023 | B530: 2022-06-01 | C530: 5 | D530: 47946 | E530: Expresso | F530: 2.2 | G530: 1.5 | H530: 3.3 | I530: 4.4 | J530: 1.1 | K530: note isolée (non rattachée) | M530: =CEILING(G530,1)*F530 -> 4.4 | N530: =M530-H530 -> 1.1 | O530: =IF(ABS(N530-J530)<0.011,1,0) -> 1
A531: 2022-2023 | B531: 2022-06-01 | C531: 5 | D531: 47946 | E531: MORTEAU GRILLEE | F531: 17.6 | G531: 0.5 | H531: 8.8 | I531: 17.6 | J531: 8.8 | K531: note isolée (non rattachée) | M531: =CEILING(G531,1)*F531 -> 17.6 | N531: =M531-H531 -> 8.8 | O531: =IF(ABS(N531-J531)<0.011,1,0) -> 1
A532: 2022-2023 | B532: 2022-06-01 | C532: 5 | D532: 47946 | E532: TRUITE JURASSIENNE | F532: 17.6 | G532: 0.5 | H532: 8.8 | I532: 17.6 | J532: 8.8 | K532: note isolée (non rattachée) | M532: =CEILING(G532,1)*F532 -> 17.6 | N532: =M532-H532 -> 8.8 | O532: =IF(ABS(N532-J532)<0.011,1,0) -> 1
A533: 2022-2023 | B533: 2022-06-01 | C533: 5 | D533: 47946 | E533: Verre de vin | F533: 3.6 | G533: 0.5 | H533: 1.8 | I533: 3.6 | J533: 1.8 | K533: note isolée (non rattachée) | M533: =CEILING(G533,1)*F533 -> 3.6 | N533: =M533-H533 -> 1.8 | O533: =IF(ABS(N533-J533)<0.011,1,0) -> 1
A534: 2022-2023 | B534: 2022-06-01 | C534: 8 | D534: 47947 | E534: Baba au Macvin | F534: 6.9 | G534: 0.5 | H534: 3.45 | I534: 6.9 | J534: 3.45 | K534: refermé (somme entière) | L534: n° 8 + n° 9 | M534: =CEILING(G534,1)*F534 -> 6.9 | N534: =M534-H534 -> 3.45 | O534: =IF(ABS(N534-J534)<0.011,1,0) -> 1
A535: 2022-2023 | B535: 2022-06-01 | C535: 8 | D535: 47947 | E535: Crêpe Nutella | F535: 4.7 | G535: 0.5 | H535: 2.35 | I535: 4.7 | J535: 2.35 | K535: refermé (somme entière) | L535: n° 8 + n° 9 | M535: =CEILING(G535,1)*F535 -> 4.7 | N535: =M535-H535 -> 2.35 | O535: =IF(ABS(N535-J535)<0.011,1,0) -> 1
A536: 2022-2023 | B536: 2022-06-01 | C536: 8 | D536: 47947 | E536: Orangina (25cl) | F536: 3.9 | G536: 0.5 | H536: 1.95 | I536: 3.9 | J536: 1.95 | K536: refermé (somme entière) | L536: n° 8 + n° 9 | M536: =CEILING(G536,1)*F536 -> 3.9 | N536: =M536-H536 -> 1.95 | O536: =IF(ABS(N536-J536)<0.011,1,0) -> 1
A537: 2022-2023 | B537: 2022-06-01 | C537: 8 | D537: 47947 | E537: San Pelegrino | F537: 5.9 | G537: 0.5 | H537: 2.95 | I537: 5.9 | J537: 2.95 | K537: refermé (somme entière) | L537: n° 8 + n° 9 | M537: =CEILING(G537,1)*F537 -> 5.9 | N537: =M537-H537 -> 2.95 | O537: =IF(ABS(N537-J537)<0.011,1,0) -> 1
...

Sheet Synthèse
A1: LE CHIFFRAGE DU SERVICE (proposition du 18/05/2026, p. 22) RECOMPOSÉ LIGNE À LIGNE SUR LES ANNEXES C-1 À C-3
A2: Toutes les cellules chiffrées sont des formules sur l’onglet « Lignes C » (SUMIFS / COUNTIFS). Les constantes de la ligne 5 sont les montants écrits par le service p. 22.
A4: Indicateur | B4: 2022-2023 | C4: 2023-2024 | D4: 2024-2025 | E4: 3 exercices
A5: Montant « occulté » écrit par le service (p. 22) (€) | B5: 20035.6 | C5: 22397.96 | D5: 20054.31 | E5: =SUM(B5:D5) -> 62487.87
A6: Somme de la colonne D du service sur les lignes fractionnaires (€) | B6: =SUMIFS('Lignes C'!$J$2:$J$11027,'Lignes C'!$A$2:$A$11027,"2022-2023") -> 20035.6 | C6: =SUMIFS('Lignes C'!$J$2:$J$11027,'Lignes C'!$A$2:$A$11027,"2023-2024") -> 22397.96 | D6: =SUMIFS('Lignes C'!$J$2:$J$11027,'Lignes C'!$A$2:$A$11027,"2024-2025") -> 20054.31 | E6: =SUM(B6:D6) -> 62487.87
A7: Écart (€) | B7: =B6-B5 -> 0 | C7: =C6-C5 -> 0 | D7: =D6-D5 -> 0 | E7: =E6-E5 -> 0
A8: Lignes fractionnaires (nombre) | B8: =COUNTIFS('Lignes C'!$A$2:$A$11027,"2022-2023") -> 3839 | C8: =COUNTIFS('Lignes C'!$A$2:$A$11027,"2023-2024") -> 3809 | D8: =COUNTIFS('Lignes C'!$A$2:$A$11027,"2024-2025") -> 3378 | E8: =SUM(B8:D8) -> 11026
A9: dont col. D = PU × entier supérieur − encaissé (nombre) | B9: =SUMIFS('Lignes C'!$O$2:$O$11027,'Lignes C'!$A$2:$A$11027,"2022-2023") -> 3838 | C9: =SUMIFS('Lignes C'!$O$2:$O$11027,'Lignes C'!$A$2:$A$11027,"2023-2024") -> 3807 | D9: =SUMIFS('Lignes C'!$O$2:$O$11027,'Lignes C'!$A$2:$A$11027,"2024-2025") -> 3378 | E9: =SUM(B9:D9) -> 11023
A10: Montant réellement encaissé sur ces lignes (col. 17) (€) | B10: =SUMIFS('Lignes C'!$H$2:$H$11027,'Lignes C'!$A$2:$A$11027,"2022-2023") -> 19141.7 | C10: =SUMIFS('Lignes C'!$H$2:$H$11027,'Lignes C'!$A$2:$A$11027,"2023-2024") -> 22305.44 | D10: =SUMIFS('Lignes C'!$H$2:$H$11027,'Lignes C'!$A$2:$A$11027,"2024-2025") -> 21574.39 | E10: =SUM(B10:D10) -> 63021.53
A12: Décomposition du chiffrage du service selon le sort de l’article dans la recomposition (pièce R2-quantites-recomposition.xlsx)
A13: Statut | B13: 2022-2023 | C13: 2023-2024 | D13: 2024-2025 | E13: 3 exercices
A14: Col. D du service, lignes « refermé (somme entière) » (€) | B14: =SUMIFS('Lignes C'!$J$2:$J$11027,'Lignes C'!$A$2:$A$11027,"2022-2023",'Lignes C'!$K$2:$K$11027,"refermé (somme entière)") -> 18905.71 | C14: =SUMIFS('Lignes C'!$J$2:$J$11027,'Lignes C'!$A$2:$A$11027,"2023-2024",'Lignes C'!$K$2:$K$11027,"refermé (somme entière)") -> 21389.58 | D14: =SUMIFS('Lignes C'!$J$2:$J$11027,'Lignes C'!$A$2:$A$11027,"2024-2025",'Lignes C'!$K$2:$K$11027,"refermé (somme entière)") -> 19524.86 | E14: =SUM(B14:D14) -> 59820.15
A15: Col. D du service, lignes « note isolée (non rattachée) » (€) | B15: =SUMIFS('Lignes C'!$J$2:$J$11027,'Lignes C'!$A$2:$A$11027,"2022-2023",'Lignes C'!$K$2:$K$11027,"note isolée (non rattachée)") -> 681.5 | C15: =SUMIFS('Lignes C'!$J$2:$J$11027,'Lignes C'!$A$2:$A$11027,"2023-2024",'Lignes C'!$K$2:$K$11027,"note isolée (non rattachée)") -> 720.95 | D15: =SUMIFS('Lignes C'!$J$2:$J$11027,'Lignes C'!$A$2:$A$11027,"2024-2025",'Lignes C'!$K$2:$K$11027,"note isolée (non rattachée)") -> 529.45 | E15: =SUM(B15:D15) -> 1931.9
A16: Col. D du service, lignes « résidu (8 tables) » (€) | B16: =SUMIFS('Lignes C'!$J$2:$J$11027,'Lignes C'!$A$2:$A$11027,"2022-2023",'Lignes C'!$K$2:$K$11027,"résidu (8 tables)") -> 448.39 | C16: =SUMIFS('Lignes C'!$J$2:$J$11027,'Lignes C'!$A$2:$A$11027,"2023-2024",'Lignes C'!$K$2:$K$11027,"résidu (8 tables)") -> 287.43 | D16: =SUMIFS('Lignes C'!$J$2:$J$11027,'Lignes C'!$A$2:$A$11027,"2024-2025",'Lignes C'!$K$2:$K$11027,"résidu (8 tables)") -> 0 | E16: =SUM(B16:D16) -> 735.82
A17: Total (= ligne 6) (€) | B17: =SUM(B14:B16) -> 20035.6 | C17: =SUM(C14:C16) -> 22397.96 | D17: =SUM(D14:D16) -> 20054.31 | E17: =SUM(B17:D17) -> 62487.87
A18: Part des lignes refermées dans le chiffrage du service | B18: =B14/B17 -> 0.94360588 | C18: =C14/C17 -> 0.95497894 | D18: =D14/D17 -> 0.97359919 | E18: =E14/E17 -> 0.95730819
A19: Lignes « refermé (somme entière) » (nombre) | B19: =COUNTIFS('Lignes C'!$A$2:$A$11027,"2022-2023",'Lignes C'!$K$2:$K$11027,"refermé (somme entière)") -> 3622 | C19: =COUNTIFS('Lignes C'!$A$2:$A$11027,"2023-2024",'Lignes C'!$K$2:$K$11027,"refermé (somme entière)") -> 3658 | D19: =COUNTIFS('Lignes C'!$A$2:$A$11027,"2024-2025",'Lignes C'!$K$2:$K$11027,"refermé (somme entière)") -> 3295 | E19: =SUM(B19:D19) -> 10575
A20: Lignes « note isolée (non rattachée) » (nombre) | B20: =COUNTIFS('Lignes C'!$A$2:$A$11027,"2022-2023",'Lignes C'!$K$2:$K$11027,"note isolée (non rattachée)") -> 145 | C20: =COUNTIFS('Lignes C'!$A$2:$A$11027,"2023-2024",'Lignes C'!$K$2:$K$11027,"note isolée (non rattachée)") -> 113 | D20: =COUNTIFS('Lignes C'!$A$2:$A$11027,"2024-2025",'Lignes C'!$K$2:$K$11027,"note isolée (non rattachée)") -> 83 | E20: =SUM(B20:D20) -> 341
A21: Lignes « résidu (8 tables) » (nombre) | B21: =COUNTIFS('Lignes C'!$A$2:$A$11027,"2022-2023",'Lignes C'!$K$2:$K$11027,"résidu (8 tables)") -> 72 | C21: =COUNTIFS('Lignes C'!$A$2:$A$11027,"2023-2024",'Lignes C'!$K$2:$K$11027,"résidu (8 tables)") -> 38 | D21: =COUNTIFS('Lignes C'!$A$2:$A$11027,"2024-2025",'Lignes C'!$K$2:$K$11027,"résidu (8 tables)") -> 0 | E21: =SUM(B21:D21) -> 110
A22: Encaissé sur les lignes « refermé (somme entière) » (€) | B22: =SUMIFS('Lignes C'!$H$2:$H$11027,'Lignes C'!$A$2:$A$11027,"2022-2023",'Lignes C'!$K$2:$K$11027,"refermé (somme entière)") -> 18225.49 | C22: =SUMIFS('Lignes C'!$H$2:$H$11027,'Lignes C'!$A$2:$A$11027,"2023-2024",'Lignes C'!$K$2:$K$11027,"refermé (somme entière)") -> 21254.22 | D22: =SUMIFS('Lignes C'!$H$2:$H$11027,'Lignes C'!$A$2:$A$11027,"2024-2025",'Lignes C'!$K$2:$K$11027,"refermé (somme entière)") -> 21032.34 | E22: =SUM(B22:D22) -> 60512.05
A23: Encaissé sur les lignes « note isolée (non rattachée) » (€) | B23: =SUMIFS('Lignes C'!$H$2:$H$11027,'Lignes C'!$A$2:$A$11027,"2022-2023",'Lignes C'!$K$2:$K$11027,"note isolée (non rattachée)") -> 693.8 | C23: =SUMIFS('Lignes C'!$H$2:$H$11027,'Lignes C'!$A$2:$A$11027,"2023-2024",'Lignes C'!$K$2:$K$11027,"note isolée (non rattachée)") -> 818.35 | D23: =SUMIFS('Lignes C'!$H$2:$H$11027,'Lignes C'!$A$2:$A$11027,"2024-2025",'Lignes C'!$K$2:$K$11027,"note isolée (non rattachée)") -> 542.05 | E23: =SUM(B23:D23) -> 2054.2
A24: Encaissé sur les lignes « résidu (8 tables) » (€) | B24: =SUMIFS('Lignes C'!$H$2:$H$11027,'Lignes C'!$A$2:$A$11027,"2022-2023",'Lignes C'!$K$2:$K$11027,"résidu (8 tables)") -> 222.41 | C24: =SUMIFS('Lignes C'!$H$2:$H$11027,'Lignes C'!$A$2:$A$11027,"2023-2024",'Lignes C'!$K$2:$K$11027,"résidu (8 tables)") -> 232.87 | D24: =SUMIFS('Lignes C'!$H$2:$H$11027,'Lignes C'!$A$2:$A$11027,"2024-2025",'Lignes C'!$K$2:$K$11027,"résidu (8 tables)") -> 0 | E24: =SUM(B24:D24) -> 455.28
A26: Lecture : pour une paire 0,50 + 0,50, la colonne D vaut PU/2 sur chaque note, soit PU au total : le service compte comme « occulté » le prix entier d’un article servi une fois et payé une fois.

Sheet Exemples annexe B
A1: LIGNES DE L’ANNEXE B DU SERVICE (prix-vente-quantité) POUR LES TABLES CITÉES DANS LA PAGE : la note de clôture porte la quantité entière cumulée de la table, et l’« écart » du service (col. B) est le montant déjà payé par les autres notes.
A3: Exercice | B3: Date | C3: N° note | D3: Article | E3: Qté (annexe B) | F3: PU (€) | G3: Total TTC de la ligne (€) | H3: Col. A du service « Prix TTC × Qté » (€) | I3: Col. B du service « Écart A − 10 » (€) | J3: Recalcul : PU × Qté (€) | K3: Recalcul : Total TTC − PU × Qté (signe de la col. B du service) (€) | L3: Lecture
A4: 2022-2023 | B4: 2022-04-14 | C4: 13 | D4: CABRICHOU | E4: 0.5 | F4: 15.9 | G4: 7.95 | H4: 7.95 | I4: 0 | J4: =F4*E4 -> 7.95 | K4: =G4-J4 -> 0 | L4: part du convive (fraction), écart 0
A5: 2022-2023 | B5: 2022-04-14 | C5: 13 | D5: Cidre Bouché Brut | E5: 0.5 | F5: 14 | G5: 7 | H5: 7 | I5: 0 | J5: =F5*E5 -> 7 | K5: =G5-J5 -> 0 | L5: part du convive (fraction), écart 0
A6: 2022-2023 | B6: 2022-04-14 | C6: 13 | D6: Expresso | E6: 1 | F6: 2.2 | G6: 2.2 | H6: 2.2 | I6: 0 | J6: =F6*E6 -> 2.2 | K6: =G6-J6 -> 0
A7: 2022-2023 | B7: 2022-04-14 | C7: 13 | D7: FRELEE | E7: 0.5 | F7: 18.6 | G7: 9.3 | H7: 9.3 | I7: 0 | J7: =F7*E7 -> 9.3 | K7: =G7-J7 -> 0 | L7: part du convive (fraction), écart 0
A8: 2022-2023 | B8: 2022-04-14 | C8: 14 | D8: CABRICHOU | E8: 1 | F8: 15.9 | G8: 7.95 | H8: 15.9 | I8: -7.95 | J8: =F8*E8 -> 15.9 | K8: =G8-J8 -> -7.95 | L8: note de clôture : quantité cumulée de la table, écart = payé par les autres notes
A9: 2022-2023 | B9: 2022-04-14 | C9: 14 | D9: Cidre Bouché Brut | E9: 1 | F9: 14 | G9: 7 | H9: 14 | I9: -7 | J9: =F9*E9 -> 14 | K9: =G9-J9 -> -7 | L9: note de clôture : quantité cumulée de la table, écart = payé par les autres notes
A10: 2022-2023 | B10: 2022-04-14 | C10: 14 | D10: Expresso | E10: 2 | F10: 2.2 | G10: 2.2 | H10: 4.4 | I10: -2.2 | J10: =F10*E10 -> 4.4 | K10: =G10-J10 -> -2.2 | L10: note de clôture : quantité cumulée de la table, écart = payé par les autres notes
A11: 2022-2023 | B11: 2022-04-14 | C11: 14 | D11: FRELEE | E11: 1 | F11: 18.6 | G11: 9.3 | H11: 18.6 | I11: -9.3 | J11: =F11*E11 -> 18.6 | K11: =G11-J11 -> -9.3 | L11: note de clôture : quantité cumulée de la table, écart = payé par les autres notes
A13: 2022-2023 | B13: 2022-04-29 | C13: 4 | D13: CAMEMBERT ROTI | E13: 0.33 | F13: 17.6 | G13: 5.81 | H13: 5.808 | I13: 0.002 | J13: =F13*E13 -> 5.808 | K13: =G13-J13 -> 0.002 | L13: part du convive (fraction), écart 0
A14: 2022-2023 | B14: 2022-04-29 | C14: 4 | D14: Coca (25cl) | E14: 0.33 | F14: 3.9 | G14: 1.29 | H14: 1.287 | I14: 0.003 | J14: =F14*E14 -> 1.287 | K14: =G14-J14 -> 0.003 | L14: part du convive (fraction), écart 0
A15: 2022-2023 | B15: 2022-04-29 | C15: 4 | D15: PAYSANNE | E15: 0.33 | F15: 19.9 | G15: 6.57 | H15: 6.567 | I15: 0.003 | J15: =F15*E15 -> 6.567 | K15: =G15-J15 -> 0.003 | L15: part du convive (fraction), écart 0
A16: 2022-2023 | B16: 2022-04-29 | C16: 4 | D16: Salade Régionale | E16: 0.33 | F16: 19.9 | G16: 6.57 | H16: 6.567 | I16: 0.003 | J16: =F16*E16 -> 6.567 | K16: =G16-J16 -> 0.003 | L16: part du convive (fraction), écart 0
A17: 2022-2023 | B17: 2022-04-29 | C17: 4 | D17: Sirop à l'eau | E17: 0.33 | F17: 2.2 | G17: 0.73 | H17: 0.726 | I17: 0.004 | J17: =F17*E17 -> 0.726 | K17: =G17-J17 -> 0.004 | L17: part du convive (fraction), écart 0
A18: 2022-2023 | B18: 2022-04-29 | C18: 5 | D18: CAMEMBERT ROTI | E18: 0.34 | F18: 17.6 | G18: 5.98 | H18: 5.984 | I18: -0.004 | J18: =F18*E18 -> 5.984 | K18: =G18-J18 -> -0.004 | L18: part du convive (fraction), écart 0
A19: 2022-2023 | B19: 2022-04-29 | C19: 5 | D19: Coca (25cl) | E19: 0.34 | F19: 3.9 | G19: 1.33 | H19: 1.326 | I19: 0.004 | J19: =F19*E19 -> 1.326 | K19: =G19-J19 -> 0.004 | L19: part du convive (fraction), écart 0
... A30: 2023-2024 | B30: 2023-08-20 | C30: 8 | D30: Crêpe Confiture | E30: 0.5 | F30: 5.4 | G30: 2.7 | H30: 2.7 | I30: 0 | J30: =F30*E30 -> 2.7 | K30: =G30-J30 -> 0 | L30: part du convive (fraction), écart 0
A31: 2023-2024 | B31: 2023-08-20 | C31: 8 | D31: Expresso | E31: 1 | F31: 2.2 | G31: 2.2 | H31: 2.2 | I31: 0 | J31: =F31*E31 -> 2.2 | K31: =G31-J31 -> 0
A32: 2023-2024 | B32: 2023-08-20 | C32: 8 | D32: Galette nature | E32: 1 | F32: 3.9 | G32: 3.9 | H32: 3.9 | I32: 0 | J32: =F32*E32 -> 3.9 | K32: =G32-J32 -> 0
A33: 2023-2024 | B33: 2023-08-20 | C33: 8 | D33: Jus de Fruit | E33: 0.5 | F33: 4.2 | G33: 2.1 | H33: 2.1 | I33: 0 | J33: =F33*E33 -> 2.1 | K33: =G33-J33 -> 0 | L33: part du convive (fraction), écart 0
A34: 2023-2024 | B34: 2023-08-20 | C34: 8 | D34: La Vouivre | E34: 1 | F34: 5.9 | G34: 5.9 | H34: 5.9 | I34: 0 | J34: =F34*E34 -> 5.9 | K34: =G34-J34 -> 0
A35: 2023-2024 | B35: 2023-08-20 | C35: 8 | D35: Mambo | E35: 0.5 | F35: 6.5 | G35: 3.25 | H35: 3.25 | I35: 0 | J35: =F35*E35 -> 3.25 | K35: =G35-J35 -> 0 | L35: part du convive (fraction), écart 0
A36: 2023-2024 | B36: 2023-08-20 | C36: 8 | D36: PASSION | E36: 0.5 | F36: 7.3 | G36: 3.65 | H36: 3.65 | I36: 0 | J36: =F36*E36 -> 3.65 | K36: =G36-J36 -> 0 | L36: part du convive (fraction), écart 0
A37: 2023-2024 | B37: 2023-08-20 | C37: 8 | D37: Pavlova | E37: 0.5 | F37: 8.9 | G37: 4.45 | H37: 4.45 | I37: 0 | J37: =F37*E37 -> 4.45 | K37: =G37-J37 -> 0 | L37: part du convive (fraction), écart 0
A38: 2023-2024 | B38: 2023-08-20 | C38: 8 | D38: Pommes de Terre | E38: 1 | F38: 3.2 | G38: 3.2 | H38: 3.2 | I38: 0 | J38: =F38*E38 -> 3.2 | K38: =G38-J38 -> 0
A39: 2023-2024 | B39: 2023-08-20 | C39: 8 | D39: SAUCE JURASSIENNE | E39: 0.5 | F39: 6.1 | G39: 3.05 | H39: 3.05 | I39: 0 | J39: =F39*E39 -> 3.05 | K39: =G39-J39 -> 0 | L39: part du convive (fraction), écart 0
A40: 2023-2024 | B40: 2023-08-20 | C40: 8 | D40: Sauce Forestière | E40: 0.5 | F40: 7.9 | G40: 3.95 | H40: 3.95 | I40: 0 | J40: =F40*E40 -> 3.95 | K40: =G40-J40 -> 0 | L40: part du convive (fraction), écart 0
A41: 2023-2024 | B41: 2023-08-20 | C41: 8 | D41: Saucisse de Morteau | E41: 0.5 | F41: 8.9 | G41: 4.45 | H41: 4.45 | I41: 0 | J41: =F41*E41 -> 4.45 | K41: =G41-J41 -> 0 | L41: part du convive (fraction), écart 0
A42: 2023-2024 | B42: 2023-08-20 | C42: 8 | D42: Steak haché | E42: 0.5 | F42: 7.8 | G42: 3.9 | H42: 3.9 | I42: 0 | J42: =F42*E42 -> 3.9 | K42: =G42-J42 -> 0 | L42: part du convive (fraction), écart 0
A43: 2023-2024 | B43: 2023-08-20 | C43: 8 | D43: TRUITE JURASSIENNE | E43: 0.5 | F43: 18.6 | G43: 9.3 | H43: 9.3 | I43: 0 | J43: =F43*E43 -> 9.3 | K43: =G43-J43 -> 0 | L43: part du convive (fraction), écart 0
A44: 2023-2024 | B44: 2023-08-20 | C44: 8 | D44: TRUITE PESTO | E44: 0.5 | F44: 16.9 | G44: 8.45 | H44: 8.45 | I44: 0 | J44: =F44*E44 -> 8.45 | K44: =G44-J44 -> 0 | L44: part du convive (fraction), écart 0
A45: 2023-2024 | B45: 2023-08-20 | C45: 8 | D45: Verre ALIGOTE | E45: 0.5 | F45: 3.9 | G45: 1.95 | H45: 1.95 | I45: 0 | J45: =F45*E45 -> 1.95 | K45: =G45-J45 -> 0 | L45: part du convive (fraction), écart 0
A46: 2023-2024 | B46: 2023-08-20 | C46: 8 | D46: bluette | E46: 0.5 | F46: 7.9 | G46: 3.95 | H46: 3.95 | I46: 0 | J46: =F46*E46 -> 3.95 | K46: =G46-J46 -> 0 | L46: part du convive (fraction), écart 0
A47: 2023-2024 | B47: 2023-08-20 | C47: 8 | D47: pression | E47: 0.5 | F47: 4.2 | G47: 2.1 | H47: 2.1 | I47: 0 | J47: =F47*E47 -> 2.1 | K47: =G47-J47 -> 0 | L47: part du convive (fraction), écart 0
A48: 2023-2024 | B48: 2023-08-20 | C48: 8 | D48: Œuf | E48: 0.5 | F48: 0.9 | G48: 0.45 | H48: 0.45 | I48: 0 | J48: =F48*E48 -> 0.45 | K48: =G48-J48 -> 0 | L48: part du convive (fraction), écart 0
A49: 2023-2024 | B49: 2023-08-20 | C49: 9 | D49: CABRICHOU | E49: 0.25 | F49: 16.9 | G49: 4.23 | H49: 4.225 | I49: 0.005 | J49: =F49*E49 -> 4.225 | K49: =G49-J49 -> 0.005 | L49: part du convive (fraction), écart 0
A50: 2023-2024 | B50: 2023-08-20 | C50: 9 | D50: Crêpe Confiture | E50: 0.25 | F50: 5.4 | G50: 1.35 | H50: 1.35 | I50: 0 | J50: =F50*E50 -> 1.35 | K50: =G50-J50 -> 0 | L50: part du convive (fraction), écart 0
... A90: 2023-2024 | B90: 2023-05-14 | C90: 11 | D90: ASSIETTE PERE GREGOI | E90: 0.5 | F90: 18.6 | G90: 9.3 | H90: 9.3 | I90: 0 | J90: =F90*E90 -> 9.3 | K90: =G90-J90 -> 0 | L90: part du convive (fraction), écart 0
A91: 2023-2024 | B91: 2023-05-14 | C91: 11 | D91: Arbois Trousseau Le | E91: 1 | F91: 6.4 | G91: 6.4 | H91: 6.4 | I91: 0 | J91: =F91*E91 -> 6.4 | K91: =G91-J91 -> 0
...

Sheet Clôture annexe B
A1: Exercice | B1: Date | C1: Table (notes jumelles) | D1: Article | E1: PU (€) | F1: Somme des fractions (R2) | G1: Refermé ? (R2) (1/0) | H1: Entier cible = ROUND(somme) | I1: Note de clôture trouvée dans l’annexe B (n°) | J1: Qté annexe B sur cette note | K1: Total TTC annexe B (€) | L1: Col. B du service « écart » (€) | M1: Signature : Qté annexe B = entier cible (1/0)
A2: 2022-2023 | B2: 2022-04-14 | C2: n° 11 + n° 12 | D2: BARBEULENET | E2: 13.9 | F2: 1 | G2: 1 | H2: =ROUND(F2,0) -> 1 | I2: 12 | J2: 1 | K2: 6.95 | L2: -6.95 | M2: =IF(AND(J2<>"",ABS(J2-H2)<0.011),1,0) -> 1
A3: 2022-2023 | B3: 2022-04-14 | C3: n° 11 + n° 12 | D3: Croûtes Morilles | E3: 16.9 | F3: 1 | G3: 1 | H3: =ROUND(F3,0) -> 1 | I3: 12 | J3: 1 | K3: 8.45 | L3: -8.45 | M3: =IF(AND(J3<>"",ABS(J3-H3)<0.011),1,0) -> 1
A4: 2022-2023 | B4: 2022-04-14 | C4: n° 11 + n° 12 | D4: Père Gregoire | E4: 4.9 | F4: 1 | G4: 1 | H4: =ROUND(F4,0) -> 1 | I4: 12 | J4: 1 | K4: 2.45 | L4: -2.45 | M4: =IF(AND(J4<>"",ABS(J4-H4)<0.011),1,0) -> 1
A5: 2022-2023 | B5: 2022-04-14 | C5: n° 11 + n° 12 | D5: SAUCE CHOCO/CAFE/CAR | E5: 1.8 | F5: 1 | G5: 1 | H5: =ROUND(F5,0) -> 1 | I5: 12 | J5: 1 | K5: 0.9 | L5: -0.9 | M5: =IF(AND(J5<>"",ABS(J5-H5)<0.011),1,0) -> 1
A6: 2022-2023 | B6: 2022-04-14 | C6: n° 11 + n° 12 | D6: Salade Verte aux Noi | E6: 5.9 | F6: 1 | G6: 1 | H6: =ROUND(F6,0) -> 1 | I6: 12 | J6: 1 | K6: 2.95 | L6: -2.95 | M6: =IF(AND(J6<>"",ABS(J6-H6)<0.011),1,0) -> 1
A7: 2022-2023 | B7: 2022-04-14 | C7: n° 11 + n° 12 | D7: pression | E7: 3.9 | F7: 1 | G7: 1 | H7: =ROUND(F7,0) -> 1 | I7: 12 | J7: 1 | K7: 1.95 | L7: -1.95 | M7: =IF(AND(J7<>"",ABS(J7-H7)<0.011),1,0) -> 1
A8: 2022-2023 | B8: 2022-04-14 | C8: n° 13 + n° 14 | D8: CABRICHOU | E8: 15.9 | F8: 1 | G8: 1 | H8: =ROUND(F8,0) -> 1 | I8: 14 | J8: 1 | K8: 7.95 | L8: -7.95 | M8: =IF(AND(J8<>"",ABS(J8-H8)<0.011),1,0) -> 1
A9: 2022-2023 | B9: 2022-04-14 | C9: n° 13 + n° 14 | D9: Cidre Bouché Brut | E9: 14 | F9: 1 | G9: 1 | H9: =ROUND(F9,0) -> 1 | I9: 14 | J9: 1 | K9: 7 | L9: -7 | M9: =IF(AND(J9<>"",ABS(J9-H9)<0.011),1,0) -> 1
A10: 2022-2023 | B10: 2022-04-14 | C10: n° 13 + n° 14 | D10: FRELEE | E10: 18.6 | F10: 1 | G10: 1 | H10: =ROUND(F10,0) -> 1 | I10: 14 | J10: 1 | K10: 9.3 | L10: -9.3 | M10: =IF(AND(J10<>"",ABS(J10-H10)<0.011),1,0) -> 1
A11: 2022-2023 | B11: 2022-04-14 | C11: n° 15 + n° 16 | D11: Complète | E11: 11.6 | F11: 1 | G11: 1 | H11: =ROUND(F11,0) -> 1 | I11: 16 | J11: 1 | K11: 5.8 | L11: -5.8 | M11: =IF(AND(J11<>"",ABS(J11-H11)<0.011),1,0) -> 1
A12: 2022-2023 | B12: 2022-04-14 | C12: n° 15 + n° 16 | D12: Déca | E12: 2.2 | F12: 1 | G12: 1 | H12: =ROUND(F12,0) -> 1 | I12: 16 | J12: 1 | K12: 1.1 | L12: -1.1 | M12: =IF(AND(J12<>"",ABS(J12-H12)<0.011),1,0) -> 1
A13: 2022-2023 | B13: 2022-04-14 | C13: n° 15 + n° 16 | D13: Expresso | E13: 2.2 | F13: 3 | G13: 1 | H13: =ROUND(F13,0) -> 3 | I13: 16 | J13: 3 | K13: 3.3 | L13: -3.3 | M13: =IF(AND(J13<>"",ABS(J13-H13)<0.011),1,0) -> 1
... A857: 2022-2023 | B857: 2022-09-01 | C857: n° 32 + n° 33 | D857: TANTE ARIE | E857: 8.5 | F857: 1 | G857: 1 | H857: =ROUND(F857,0) -> 1 | I857: 33 | J857: 1 | K857: 4.25 | L857: -4.25 | M857: =IF(AND(J857<>"",ABS(J857-H857)<0.011),1,0) -> 1
A858: 2022-2023 | B858: 2022-09-03 | C858: n° 13 + n° 14 | D858: Beaujolais Moulin à | E858: 29 | F858: 1 | G858: 1 | H858: =ROUND(F858,0) -> 1 | M858: =IF(AND(J858<>"",ABS(J858-H858)<0.011),1,0) -> 0
A859: 2022-2023 | B859: 2022-09-03 | C859: n° 3 + n° 4 | D859: Kir Bourgogne | E859: 4.2 | F859: 1 | G859: 1 | H859: =ROUND(F859,0) -> 1 | I859: 4 | J859: 1 | K859: 2.1 | L859: -2.1 | M859: =IF(AND(J859<>"",ABS(J859-H859)<0.011),1,0) -> 1
A860: 2022-2023 | B860: 2022-09-03 | C860: n° 3 + n° 4 | D860: Mambo | E860: 6.5 | F860: 1 | G860: 1 | H860: =ROUND(F860,0) -> 1 | I860: 4 | J860: 1 | K860: 3.25 | L860: -3.25 | M860: =IF(AND(J860<>"",ABS(J860-H860)<0.011),1,0) -> 1
A861: 2022-2023 | B861: 2022-09-07 | C861: n° 19 + n° 20 | D861: Arbois Trousseau Le | E861: 6.4 | F861: 1 | G861: 1 | H861: =ROUND(F861,0) -> 1 | I861: 20 | J861: 1 | K861: 3.2 | L861: -3.2 | M861: =IF(AND(J861<>"",ABS(J861-H861)<0.011),1,0) -> 1
A862: 2022-2023 | B862: 2022-09-07 | C862: n° 19 + n° 20 | D862: Expresso Crème | E862: 2.4 | F862: 1 | G862: 1 | H862: =ROUND(F862,0) -> 1 | I862: 20 | J862: 1 | K862: 1.2 | L862: -1.2 | M862: =IF(AND(J862<>"",ABS(J862-H862)<0.011),1,0) -> 1
A863: 2022-2023 | B863: 2022-09-07 | C863: n° 19 + n° 20 | D863: Normandine | E863: 8.7 | F863: 1 | G863: 1 | H863: =ROUND(F863,0) -> 1 | I863: 20 | J863: 1 | K863: 4.35 | L863: -4.35 | M863: =IF(AND(J863<>"",ABS(J863-H863)<0.011),1,0) -> 1
A864: 2022-2023 | B864: 2022-09-08 | C864: n° 10 + n° 11 | D864: Gewurztraminer Le ve | E864: 7 | F864: 1 | G864: 1 | H864: =ROUND(F864,0) -> 1 | I864: 11 | J864: 1 | K864: 3.5 | L864: -3.5 | M864: =IF(AND(J864<>"",ABS(J864-H864)<0.011),1,0) -> 1
A865: 2022-2023 | B865: 2022-09-08 | C865: n° 10 + n° 11 | D865: Saint Véran Verre | E865: 7.9 | F865: 1 | G865: 1 | H865: =ROUND(F865,0) -> 1 | I865: 11 | J865: 1 | K865: 3.95 | L865: -3.95 | M865: =IF(AND(J865<>"",ABS(J865-H865)<0.011),1,0) -> 1
A866: 2022-2023 | B866: 2022-09-08 | C866: n° 14 + n° 15 | D866: Crêpe Confiture | E866: 4.6 | F866: 1 | G866: 1 | H866: =ROUND(F866,0) -> 1 | I866: 15 | J866: 1 | K866: 2.3 | L866: -2.3 | M866: =IF(AND(J866<>"",ABS(J866-H866)<0.011),1,0) -> 1
A867: 2022-2023 | B867: 2022-09-08 | C867: n° 14 + n° 15 | D867: Escargots de Bourgog | E867: 8 | F867: 1 | G867: 1 | H867: =ROUND(F867,0) -> 1 | I867: 15 | J867: 1 | K867: 4 | L867: -4 | M867: =IF(AND(J867<>"",ABS(J867-H867)<0.011),1,0) -> 1
A868: 2022-2023 | B868: 2022-09-08 | C868: n° 14 + n° 15 | D868: GLACE 2 BOULES | E868: 3.9 | F868: 1 | G868: 1 | H868: =ROUND(F868,0) -> 1 | I868: 15 | J868: 1 | K868: 1.95 | L868: -1.95 | M868: =IF(AND(J868<>"",ABS(J868-H868)<0.011),1,0) -> 1
A869: 2022-2023 | B869: 2022-09-08 | C869: n° 14 + n° 15 | D869: Jamhon Persillé | E869: 7.2 | F869: 1 | G869: 1 | H869: =ROUND(F869,0) -> 1 | I869: 15 | J869: 1 | K869: 3.6 | L869: -3.6 | M869: =IF(AND(J869<>"",ABS(J869-H869)<0.011),1,0) -> 1
A870: 2022-2023 | B870: 2022-09-08 | C870: n° 14 + n° 15 | D870: PICHET SAINT VERAN | E870: 30 | F870: 1 | G870: 1 | H870: =ROUND(F870,0) -> 1 | I870: 15 | J870: 1 | K870: 15 | L870: -15 | M870: =IF(AND(J870<>"",ABS(J870-H870)<0.011),1,0) -> 1
... A1004: 2022-2023 | B1004: 2022-10-05 | C1004: n° 6 + n° 7 | D1004: TRUITE PESTO | E1004: 15.9 | F1004: 1 | G1004: 1 | H1004: =ROUND(F1004,0) -> 1 | I1004: 7 | J1004: 1 | K1004: 7.95 | L1004: -7.95 | M1004: =IF(AND(J1004<>"",ABS(J1004-H1004)<0.011),1,0) -> 1
A1005: 2022-2023 | B1005: 2022-10-06 | C1005: n° 19 + n° 20 | D1005: Saint Véran | E1005: 39.5 | F1005: 1 | G1005: 1 | H1005: =ROUND(F1005,0) -> 1 | M1005: =IF(AND(J1005<>"",ABS(J1005-H1005)<0.011),1,0) -> 0
A1006: 2022-2023 | B1006: 2022-10-06 | C1006: n° 4 + n° 5 | D1006: H.C.DE BEAUNE VERRE | E1006: 7.9 | F1006: 1 | G1006: 1 | H1006: =ROUND(F1006,0) -> 1 | I1006: 5 | J1006: 1 | K1006: 3.95 | L1006: -3.95 | M1006: =IF(AND(J1006<>"",ABS(J1006-H1006)<0.011),1,0) -> 1
A1007: 2022-2023 | B1007: 2022-10-06 | C1007: n° 4 + n° 5 | D1007: Savagnin verre | E1007: 7.2 | F1007: 1 | G1007: 1 | H1007: =ROUND(F1007,0) -> 1 | I1007: 5 | J1007: 1 | K1007: 3.6 | L1007: -3.6 | M1007: =IF(AND(J1007<>"",ABS(J1007-H1007)<0.011),1,0) -> 1
A1008: 2022-2023 | B1008: 2022-10-07 | C1008: n° 17 + n° 18 | D1008: MAEVA | E1008: 9 | F1008: 1 | G1008: 1 | H1008: =ROUND(F1008,0) -> 1 | I1008: 18 | J1008: 1 | K1008: 4.5 | L1008: -4.5 | M1008: =IF(AND(J1008<>"",ABS(J1008-H1008)<0.011),1,0) -> 1
A1009: 2022-2023 | B1009: 2022-10-07 | C1009: n° 17 + n° 18 | D1009: Rêve Bleu | E1009: 9 | F1009: 1 | G1009: 1 | H1009: =ROUND(F1009,0) -> 1 | I1009: 18 | J1009: 1 | K1009: 4.5 | L1009: -4.5 | M1009: =IF(AND(J1009<>"",ABS(J1009-H1009)<0.011),1,0) -> 1
A1010: 2022-2023 | B1010: 2022-10-07 | C1010: n° 17 + n° 18 | D1010: Saint Véran Verre | E1010: 7.9 | F1010: 1 | G1010: 1 | H1010: =ROUND(F1010,0) -> 1 | I1010: 18 | J1010: 1 | K1010: 3.95 | L1010: -3.95 | M1010: =IF(AND(J1010<>"",ABS(J1010-H1010)<0.011),1,0) -> 1
A1011: 2022-2023 | B1011: 2022-10-07 | C1011: n° 17 + n° 18 | D1011: Salade Verte | E1011: 5.9 | F1011: 1 | G1011: 1 | H1011: =ROUND(F1011,0) -> 1 | I1011: 18 | J1011: 1 | K1011: 2.95 | L1011: -2.95 | M1011: =IF(AND(J1011<>"",ABS(J1011-H1011)<0.011),1,0) -> 1
A1012: 2022-2023 | B1012: 2022-10-07 | C1012: n° 17 + n° 18 | D1012: VERRE H.C.DE BEAUNE | E1012: 7.9 | F1012: 1 | G1012: 1 | H1012: =ROUND(F1012,0) -> 1 | I1012: 18 | J1012: 1 | K1012: 3.95 | L1012: -3.95 | M1012: =IF(AND(J1012<>"",ABS(J1012-H1012)<0.011),1,0) -> 1
A1013: 2022-2023 | B1013: 2022-10-07 | C1013: n° 22 + n° 23 | D1013: 1 Boule Glace | E1013: 2 | F1013: 1 | G1013: 1 | H1013: =ROUND(F1013,0) -> 1 | I1013: 23 | J1013: 1 | K1013: 1 | L1013: -1 | M1013: =IF(AND(J1013<>"",ABS(J1013-H1013)<0.011),1,0) -> 1
A1014: 2022-2023 | B1014: 2022-10-07 | C1014: n° 22 + n° 23 | D1014: ASSIETTE FRANC-COMTO | E1014: 17.6 | F1014: 1 | G1014: 1 | H1014: =ROUND(F1014,0) -> 1 | I1014: 23 | J1014: 1 | K1014: 8.8 | L1014: -8.8 | M1014: =IF(AND(J1014<>"",ABS(J1014-H1014)<0.011),1,0) -> 1
A1015: 2022-2023 | B1015: 2022-10-07 | C1015: n° 22 + n° 23 | D1015: CREME BRULEE | E1015: 6.9 | F1015: 1 | G1015: 1 | H1015: =ROUND(F1015,0) -> 1 | I1015: 23 | J1015: 1 | K1015: 3.45 | L1015: -3.45 | M1015: =IF(AND(J1015<>"",ABS(J1015-H1015)<0.011),1,0) -> 1
A1016: 2022-2023 | B1016: 2022-10-07 | C1016: n° 22 + n° 23 | D1016: CREPE CHOC/CHANTILLY | E1016: 6.5 | F1016: 1 | G1016: 1 | H1016: =ROUND(F1016,0) -> 1 | I1016: 23 | J1016: 1 | K1016: 3.25 | L1016: -3.25 | M1016: =IF(AND(J1016<>"",ABS(J1016-H1016)<0.011),1,0) -> 1
...

Sheet Synthèse clôture
A1: LA NOTE DE CLÔTURE DANS L’ANNEXE B DU SERVICE : pour chaque article refermé de la pièce R2, l’annexe B porte-t-elle, sur une note de la table, l’article à la quantité entière cumulée ?
A2: Formules COUNTIFS sur l’onglet « Clôture annexe B ».
A4: Indicateur | B4: 2022-2023 | C4: 2023-2024 | D4: 2024-2025 | E4: 3 exercices
A5: Articles fractionnés recomposés (R2) | B5: =COUNTIFS('Clôture annexe B'!$A$2:$A$5063,"2022-2023") -> 1666 | C5: =COUNTIFS('Clôture annexe B'!$A$2:$A$5063,"2023-2024") -> 1781 | D5: =COUNTIFS('Clôture annexe B'!$A$2:$A$5063,"2024-2025") -> 1615 | E5: =SUM(B5:D5) -> 5062
A6: dont refermés (somme entière) | B6: =COUNTIFS('Clôture annexe B'!$A$2:$A$5063,"2022-2023",'Clôture annexe B'!$G$2:$G$5063,1) -> 1641 | C6: =COUNTIFS('Clôture annexe B'!$A$2:$A$5063,"2023-2024",'Clôture annexe B'!$G$2:$G$5063,1) -> 1756 | D6: =COUNTIFS('Clôture annexe B'!$A$2:$A$5063,"2024-2025",'Clôture annexe B'!$G$2:$G$5063,1) -> 1615 | E6: =SUM(B6:D6) -> 5012
A7: dont refermés ET note de clôture à la quantité entière dans l’annexe B | B7: =COUNTIFS('Clôture annexe B'!$A$2:$A$5063,"2022-2023",'Clôture annexe B'!$G$2:$G$5063,1,'Clôture annexe B'!$M$2:$M$5063,1) -> 1618 | C7: =COUNTIFS('Clôture annexe B'!$A$2:$A$5063,"2023-2024",'Clôture annexe B'!$G$2:$G$5063,1,'Clôture annexe B'!$M$2:$M$5063,1) -> 1730 | D7: =COUNTIFS('Clôture annexe B'!$A$2:$A$5063,"2024-2025",'Clôture annexe B'!$G$2:$G$5063,1,'Clôture annexe B'!$M$2:$M$5063,1) -> 1601 | E7: =SUM(B7:D7) -> 4949
A8: Taux | B8: =B7/B6 -> 0.98598416 | C8: =C7/C6 -> 0.98519362 | D8: =D7/D6 -> 0.99133127 | E8: =E7/E6 -> 0.98743017
A9: Refermés avec note de clôture à une autre quantité entière (tables regroupant deux partages) | B9: =COUNTIFS('Clôture annexe B'!$A$2:$A$5063,"2022-2023",'Clôture annexe B'!$G$2:$G$5063,1,'Clôture annexe B'!$M$2:$M$5063,0,'Clôture annexe B'!$I$2:$I$5063,"<>") -> 20 | C9: =COUNTIFS('Clôture annexe B'!$A$2:$A$5063,"2023-2024",'Clôture annexe B'!$G$2:$G$5063,1,'Clôture annexe B'!$M$2:$M$5063,0,'Clôture annexe B'!$I$2:$I$5063,"<>") -> 19 | D9: =COUNTIFS('Clôture annexe B'!$A$2:$A$5063,"2024-2025",'Clôture annexe B'!$G$2:$G$5063,1,'Clôture annexe B'!$M$2:$M$5063,0,'Clôture annexe B'!$I$2:$I$5063,"<>") -> 10 | E9: =SUM(B9:D9) -> 49
A10: Refermés sans note de clôture dans l’annexe B | B10: =COUNTIFS('Clôture annexe B'!$A$2:$A$5063,"2022-2023",'Clôture annexe B'!$G$2:$G$5063,1,'Clôture annexe B'!$I$2:$I$5063,"") -> 3 | C10: =COUNTIFS('Clôture annexe B'!$A$2:$A$5063,"2023-2024",'Clôture annexe B'!$G$2:$G$5063,1,'Clôture annexe B'!$I$2:$I$5063,"") -> 7 | D10: =COUNTIFS('Clôture annexe B'!$A$2:$A$5063,"2024-2025",'Clôture annexe B'!$G$2:$G$5063,1,'Clôture annexe B'!$I$2:$I$5063,"") -> 4 | E10: =SUM(B10:D10) -> 14
A11: Résidu (non refermés) avec une note de clôture dans la table | B11: =COUNTIFS('Clôture annexe B'!$A$2:$A$5063,"2022-2023",'Clôture annexe B'!$G$2:$G$5063,0,'Clôture annexe B'!$I$2:$I$5063,"<>") -> 0 | C11: =COUNTIFS('Clôture annexe B'!$A$2:$A$5063,"2023-2024",'Clôture annexe B'!$G$2:$G$5063,0,'Clôture annexe B'!$I$2:$I$5063,"<>") -> 3 | D11: =COUNTIFS('Clôture annexe B'!$A$2:$A$5063,"2024-2025",'Clôture annexe B'!$G$2:$G$5063,0,'Clôture annexe B'!$I$2:$I$5063,"<>") -> 0 | E11: =SUM(B11:D11) -> 3
A13: Comptages bruts de l’annexe B (valeurs relevées, lignes 2 à fin de chaque fichier)
A14: Lignes à quantité fractionnaire (part d’un convive) | B14: 2174 | C14: 2040 | D14: 1753 | E14: =SUM(B14:D14) -> 5967
A15: Lignes de clôture (quantité entière, écart du service négatif) | B15: 2336 | C15: 2469 | D15: 2344 | E15: =SUM(B15:D15) -> 7149
A16: Somme des écarts négatifs du service (col. B) (€) | B16: -17561.64 | C16: -20011.41 | D16: -20115.5 | E16: =SUM(B16:D16) -> -57688.55
A17: Total de la colonne B porté en pied de l’annexe B par le service (€) | B17: -17561 | C17: -20011.12 | D17: -20115.28 | E17: =SUM(B17:D17) -> -57687.4

Sheet Méthode
A1: Objet
A2: Recomposer le montant de « chiffre d’affaires occulté » écrit par le service p. 22 de la proposition du 18/05/2026 (20 035,60 € / 22 397,96 € / 20 054,31 €) à partir de ses propres annexes C-1 à C-3, puis le ventiler selon le sort de chaque article dans la recomposition des tables partagées (pièce R2-quantites-recomposition.xlsx).
A4: Sources
A5: ANNEXE-C1 / C2 / C3 (détail des tickets) : colonnes 12 (Qté), 14 (Uprice_wt), 17 (Tot_rem Ttc), C (« Prix TTC (14) × Qté virgule neutralisée ») et D (« Écart C − 17 ») telles qu’elles figurent dans les fichiers remis par le service. ANNEXE-B1 / B2 / B3 (prix de vente / quantité) : colonnes 6 (Qté), 8 (Prix de vente TTC), 10 (Total TTC), A (Prix TTC × Qté) et B (Écart A − 10).
A7: Onglet « Lignes C »
A8: Les 11 026 lignes des annexes C dont la quantité n’est pas un entier (3 839 / 3 809 / 3 378), recopiées avec leurs colonnes C et D telles que calculées par le service. Les colonnes M à O recalculent par formule PU × entier supérieur − encaissé et vérifient que la colonne D du service suit cette règle (11 023 lignes sur 11 026 ; 3 lignes à quantité 2,25 ou 2,50 s’en écartent dans le fichier du service).
A10: Statut
A11: Chaque ligne est rattachée, par (exercice, date, numéro de note, article, prix), à l’article de la pièce R2-quantites-recomposition.xlsx : « refermé » si la somme des fractions de la table est entière, « résidu » sinon ; « note isolée » si la note n’appartient à aucune table reconstituée (64 notes).
A13: Onglet « Clôture annexe B »
A14: Pour chacun des 5 062 articles de la pièce R2, recherche dans l’annexe B, parmi les notes de la table, d’une ligne du même article à quantité entière et à écart négatif (colonne B du service). Cette ligne est la note de clôture : la caisse y porte la quantité cumulée de la table. La signature est vérifiée par formule : quantité annexe B = entier cible (arrondi de la somme des fractions).
A16: Limites
A17: La lecture « quantité cumulée sur la note de clôture » est une observation des fichiers du service (annexe B), confirmée sur 4 949 des 5 012 articles refermés et illustrée p. 21 de la proposition ; elle n’est pas documentée par l’éditeur du logiciel. 14 articles refermés n’ont pas de note de clôture dans l’annexe B ; 49 en ont une à une autre quantité entière (tables regroupant deux partages distincts).
