Workbook

Sheet Méthode
A1: R2 — Suppressions de notes (« DEL ») : rapprochement DEL vs encaissements, exercice 2022-2023
A3: OBJET. Pièce recalculée à formules, à partir des seules annexes de caisse remises au titre de l'article L. 47 A, II du LPF et
A4: effectivement présentes au dossier : ANNEXE-E1 (tpvevenement), F1 (règlements), G1 (journal TVA), H1 (liste des tickets),
A5: C1 (détail des tickets / prix pratiqués). Ces annexes couvrent le SEUL exercice 2022-2023. Les exercices 2023-2024 et
A6: 2024-2025 (annexes E2/E3, F2/F3, G2/G3, H2/H3, C2/C3) ne sont pas au dossier : aucune statistique n'est produite ici pour
A7: eux ; les montants que la proposition leur attribue (140 686,55 € et 97 071,51 €) sont repris tels quels, non vérifiés.
A9: SOURCE E1. Le fichier ANNEXE-E1 porte en dernière ligne un pied de totalisation (dateEven = « Nb lignes », mf_Number = 8014,
A10: amount = 193 005,09 €) qui n'est pas une opération : il est écarté. Restent 8 014 lignes « DEL », total 193 005,09 € —
A11: chiffres identiques au tableau de la proposition (8 014 / 193 005,09 € pour 2022-2023).
A13: CATALOGUE (onglet Catalogue_prix) : prix unitaires TTC pratiqués en 2022-2023, colonne 14 « Uprice_wt » de l'ANNEXE-C1
A14: (>0, dédoublonnés) : 258 valeurs.
A16: CLASSEMENT (onglet Sources_DEL). Pour chaque montant on cherche un prix p du catalogue et un entier k tels que
... A39: à lui seul, une preuve.

Sheet Calcul
A1: Agrégats — toutes les cellules de résultat sont des formules sur Sources_DEL
A2: Lignes « DEL » (total) | B2: =COUNT(Sources_DEL!$D$3:$D$8016)
A3: Montant total supprimé (€) | B3: =ROUND(SUM(Sources_DEL!$D$3:$D$8016),2)
A5: Lignes valant un prix unitaire de la carte | B5: =COUNTIF(Sources_DEL!$J$3:$J$8016,"carte")
A6: Euros des lignes « prix de la carte » | B6: =ROUND(SUMIF(Sources_DEL!$J$3:$J$8016,"carte",Sources_DEL!$D$3:$D$8016),2)
A7: Lignes valant une quantité entière × un prix | B7: =COUNTIF(Sources_DEL!$J$3:$J$8016,"multiple")
A8: Euros des lignes « multiple entier » | B8: =ROUND(SUMIF(Sources_DEL!$J$3:$J$8016,"multiple",Sources_DEL!$D$3:$D$8016),2)
A9: Lignes sans correspondance de prix | B9: =COUNTIF(Sources_DEL!$J$3:$J$8016,"none")
A10: Euros des lignes sans correspondance | B10: =ROUND(SUMIF(Sources_DEL!$J$3:$J$8016,"none",Sources_DEL!$D$3:$D$8016),2)
A12: Lignes expliquées par un prix (carte + multiple) | B12: =B5+B7
A13: Part en lignes | B13: =(B5+B7)/B2
A14: Part en euros (carte + multiple) | B14: =(B6+B8)/B3
A16: Contrôle : egal_montant = 1 là où un prix est trouvé | B16: =SUM(Sources_DEL!$I$3:$I$8016)
A17: … doit égaler (carte + multiple) lignes | B17: =B5+B7
A19: Lignes aberrantes de montant >= 1 000 € — nombre | B19: =COUNTIF(Sources_DEL!$D$3:$D$8016,">=1000")
A20: Lignes aberrantes >= 1 000 € — euros | B20: =ROUND(SUMIF(Sources_DEL!$D$3:$D$8016,">=1000",Sources_DEL!$D$3:$D$8016),2)
A21: Part en euros des 2 lignes aberrantes | B21: =B20/B3
A22: Euros « multiple » hors lignes aberrantes | B22: =ROUND(B8-B20,2)
A24: Médiane des montants supprimés (€) | B24: =MEDIAN(Sources_DEL!$D$3:$D$8016)
A25: Moyenne des montants supprimés (€) | B25: =ROUND(AVERAGE(Sources_DEL!$D$3:$D$8016),2)
A26: Valeurs distinctes prises par les montants « DEL » | B26: =SUMPRODUCT(1/COUNTIF(Sources_DEL!$D$3:$D$8016,Sources_DEL!$D$3:$D$8016))

Sheet Grosses_lignes
A1: Re-traçage des lignes « DEL » >= 1 000 € (exercice 2022-2023)
B3: 26/07/2022 (Z 3015) | C3: 07/08/2022 (Z 3026)
A4: Montant de la ligne « DEL » supprimée (€) | B4: 68993.1 | C4: 19600
A5: Décomposition apparente | B5: ≈ 27,40 € × 2 518 | C5: 100,00 € × 196
A6: Notes réellement encaissées ce jour-là | B6: 32 | C6: 31
A7: CA réellement encaissé ce jour (€) | B7: 2563.4 | C7: 2209.6
A8: Plus grosse note encaissée ce jour (€) | B8: 165.5 | C8: 131.2
A9: Plus grosse note de TOUT l'exercice 2022-2023 (€) | B9: 513.3 | C9: 513.3
A10: La ligne « DEL » vaut, en multiple du CA du jour | B10: =B4/B7 | C10: =C4/C7
A11: La ligne « DEL » vaut, en multiple de la plus grosse note | B11: =B4/B9 | C11: =C4/C9
A13: Conclusion : une recette de 68 993 € ou 19 600 € est impossible (plus grosse note de l'exercice : 513,30 €).
A14: Ces 2 lignes = erreurs de saisie sur la quantité, supprimées aussitôt ; elles pèsent pourtant 45,9 % du montant 2022-2023.

Sheet Univocite
A1: Mesure d'univocité de la clé (date + heure + montant + Z)
A3: Mesure | B3: Valeur
A4: Notes de l'exercice (ANNEXE-F1) | B4: 5658
A5: Totaux de note distincts | B5: 1637
A6: Notes partageant leur total avec une autre du même Z (moyenne/Z) | B6: 1.86
A7: Notes de l'exercice dont le total = 76,90 € | B7: 7
A8: Notes du Z 3052 (09/09/2022) dont le total = 76,90 € | B8: 1
A9: Notes du Z 3052 dont le total = 207,00 € | B9: 1
A10: Occurrences du montant 3,90 € parmi les lignes « DEL » | B10: 767
A11: Occurrences du montant 18,60 € parmi les lignes « DEL » | B11: 160
A13: Lecture : sur le Z 3052 les rafales de 12h07 et 12h23 n'ont qu'une note candidate chacune ; mais à l'échelle du
A14: fichier la clé n'est pas unique. Le rapprochement par rafale vaut comme indice, pas comme preuve par ligne.

Sheet Chainage_G1
A1: Totalisateur perpétuel « tot_sum » (ANNEXE-G1), trié croissant — contrôle de chaînage
A2: dateTicket | B2: noTicket | C2: no_zReport | D2: tot_ttc (€) | E2: tot_sum (€) | F2: delta | G2: ecart_vs_ttc
A3: 2022-04-14 | B3: 1 | C3: 2938 | D3: 67.4 | E3: 977807.18 | F3: =ROUND(E3-977739.78,2) | G3: =ROUND(F3-D3,2)
A4: 2022-04-14 | B4: 2 | C4: 2938 | D4: 20.9 | E4: 977828.08 | F4: =ROUND(E4-E3,2) | G4: =ROUND(F4-D4,2)
A5: 2022-04-14 | B5: 3 | C5: 2938 | D5: 61.4 | E5: 977889.48 | F5: =ROUND(E5-E4,2) | G5: =ROUND(F5-D5,2)
A6: 2022-04-14 | B6: 4 | C6: 2938 | D6: 23.8 | E6: 977913.28 | F6: =ROUND(E6-E5,2) | G6: =ROUND(F6-D6,2)
A7: 2022-04-14 | B7: 5 | C7: 2938 | D7: 23.8 | E7: 977937.08 | F7: =ROUND(E7-E6,2) | G7: =ROUND(F7-D7,2)
A8: 2022-04-14 | B8: 6 | C8: 2938 | D8: 33 | E8: 977970.08 | F8: =ROUND(E8-E7,2) | G8: =ROUND(F8-D8,2)
A9: 2022-04-14 | B9: 7 | C9: 2938 | D9: 59.4 | E9: 978029.48 | F9: =ROUND(E9-E8,2) | G9: =ROUND(F9-D9,2)
A10: 2022-04-14 | B10: 8 | C10: 2938 | D10: 19.9 | E10: 978049.38 | F10: =ROUND(E10-E9,2) | G10: =ROUND(F10-D10,2)
A11: 2022-04-14 | B11: 9 | C11: 2938 | D11: 19.9 | E11: 978069.28 | F11: =ROUND(E11-E10,2) | G11: =ROUND(F11-D11,2)
A12: 2022-04-14 | B12: 10 | C12: 2938 | D12: 52.2 | E12: 978121.48 | F12: =ROUND(E12-E11,2) | G12: =ROUND(F12-D12,2)
A13: 2022-04-14 | B13: 11 | C13: 2938 | D13: 29.35 | E13: 978150.83 | F13: =ROUND(E13-E12,2) | G13: =ROUND(F13-D13,2)
A14: 2022-04-14 | B14: 12 | C14: 2938 | D14: 29.35 | E14: 978180.18 | F14: =ROUND(E14-E13,2) | G14: =ROUND(F14-D14,2)
A15: 2022-04-14 | B15: 13 | C15: 2938 | D15: 26.45 | E15: 978206.63 | F15: =ROUND(E15-E14,2) | G15: =ROUND(F15-D15,2)
... A5660: 2023-03-31 | B5660: 21 | C5660: 3158 | D5660: 45.7 | E5660: 1381110.2 | F5660: =ROUND(E5660-E5659,2) | G5660: =ROUND(F5660-D5660,2)
A5662: Report à nouveau (A NOUVEAUX) | E5662: 977739.78
A5663: Compteur en fin de période (MAX) | E5663: =MAX(E3:E5660)
A5664: Progression du compteur (€) | E5664: =ROUND(MAX(E3:E5660)-977739.78,2)
A5665: Somme des tickets TTC (€) | E5665: =ROUND(SUM(D3:D5660),2)
A5666: Écart progression − somme TTC (€) | E5666: =ROUND((MAX(E3:E5660)-977739.78)-SUM(D3:D5660),2)
A5667: Nombre de tickets | E5667: =COUNT(D3:D5660)
A5668: Incréments négatifs (ruptures arrière) | E5668: =COUNTIF(F4:F5660,"<0")
A5669: Incréments ≠ TTC du ticket (|écart|>0) | E5669: =COUNTIF(G3:G5660,"<>0")

Sheet Reglements_F1
A1: Règlements 2022-2023 (ANNEXE-F1, hors pied « TOTAL ») — montant par mode
A2: mod_regl | B2: montant (€)
A3: CB | B3: 67.4
A4: CB | B4: 20.9
A5: CB | B5: 61.4
A6: CB | B6: 23.8
A7: CB | B7: 23.8
A8: CB | B8: 33
A9: CB | B9: 52.2
A10: CB | B10: 59.4
A11: CB | B11: 19.9
A12: CB | B12: 19.9
A13: CB | B13: 29.35
A14: CB | B14: 29.35
... A6428: CB | B6428: 45.9
A6430: TOTAL | B6430: =ROUND(SUM(B3:B6428),2)
A6431: CB | B6431: =ROUND(SUMIF($A$3:$A$6428,"CB",$B$3:$B$6428),2)
A6432: CHV | B6432: =ROUND(SUMIF($A$3:$A$6428,"CHV",$B$3:$B$6428),2)
A6433: TR | B6433: =ROUND(SUMIF($A$3:$A$6428,"TR",$B$3:$B$6428),2)
A6434: CHQ | B6434: =ROUND(SUMIF($A$3:$A$6428,"CHQ",$B$3:$B$6428),2)
A6435: ESP | B6435: =ROUND(SUMIF($A$3:$A$6428,"ESP",$B$3:$B$6428),2)
A6436: Espèces (ESP) — part | B6436: =SUMIF($A$3:$A$6428,"ESP",$B$3:$B$6428)/SUM(B3:B6428)
A6437: Bancarisé (hors ESP) — part | B6437: =1-SUMIF($A$3:$A$6428,"ESP",$B$3:$B$6428)/SUM(B3:B6428)
A6438: Montant DEL 2022-2023 / espèces encaissées (×) | B6438: =ROUND(Calcul!B3/SUMIF($A$3:$A$6428,"ESP",$B$3:$B$6428),1)

Sheet Tickets_zero
A1: Tickets clôturés à 0,00 € (ANNEXE-H1) et jumeau encaissé même n°/même jour
A2: date_ticket | B2: no_ticket | C2: tot_ttc | D2: jumeau
A3: 2022-04-14 | B3: 1 | C3: 0 | D3: 1
A4: 2022-04-14 | B4: 2 | C4: 0 | D4: 1
A5: 2022-04-14 | B5: 3 | C5: 0 | D5: 1
A6: 2022-04-14 | B6: 5 | C6: 0 | D6: 1
A7: 2022-04-14 | B7: 4 | C7: 0 | D7: 1
A8: 2022-04-14 | B8: 6 | C8: 0 | D8: 1
A9: 2022-04-14 | B9: 7 | C9: 0 | D9: 1
A10: 2022-04-14 | B10: 9 | C10: 0 | D10: 1
A11: 2022-04-14 | B11: 8 | C11: 0 | D11: 1
A12: 2022-04-15 | B12: 1 | C12: 0 | D12: 1
A13: 2022-04-15 | B13: 2 | C13: 0 | D13: 1
A14: 2022-04-15 | B14: 3 | C14: 0 | D14: 1
... A1192: 2023-03-30 | B1192: 1 | C1192: 0 | D1192: 1
A1194: Tickets à 0,00 € | D1194: =COUNT(D3:D1192)
A1195: … avec jumeau | D1195: =SUM(D3:D1192)
A1196: … orphelins (sans jumeau) | D1196: =COUNT(D3:D1192)-SUM(D3:D1192)

Sheet Catalogue_prix
A1: Prix unitaires TTC pratiqués 2022-2023 (ANNEXE-C1 col.14, >0, dédoublonnés)
A3: # | B3: Prix TTC (€)
A4: 1 | B4: 0.4
A5: 2 | B5: 0.5
A6: 3 | B6: 0.8
A7: 4 | B7: 0.9
A8: 5 | B8: 1.1
A9: 6 | B9: 1.2
A10: 7 | B10: 1.4
A11: 8 | B11: 1.5
A12: 9 | B12: 1.6
A13: 10 | B13: 1.7
A14: 11 | B14: 1.8
A15: 12 | B15: 1.9
... A261: 258 | B261: 100
A263: Nombre de prix distincts : | B263: =COUNT($B$4:$B$261)

Sheet Sources_DEL
A1: Lignes « DEL » 2022-2023 (ANNEXE-E1, pied « Nb lignes » écarté)
A2: dateEven | B2: heureEven | C2: no_zEport | D2: amount (€) | E2: id | F2: base_price (€) | G2: mult_k | H2: verif | I2: egal_montant | J2: categorie
A3: 2022-04-14 | B3: 11:26 | C3: 2938 | D3: 19 | E3: 36682 | F3: 19 | G3: 1 | H3: =ROUND(G3*F3,2) | I3: =IF(ROUND(H3-D3,2)=0,1,0) | J3: =IF(F3="","none",IF(G3=1,"carte","multiple"))
A4: 2022-04-14 | B4: 11:59 | C4: 2938 | D4: 3.4 | E4: 36683 | F4: 3.4 | G4: 1 | H4: =ROUND(G4*F4,2) | I4: =IF(ROUND(H4-D4,2)=0,1,0) | J4: =IF(F4="","none",IF(G4=1,"carte","multiple"))
A5: 2022-04-14 | B5: 12:06 | C5: 2938 | D5: 19.9 | E5: 36684 | F5: 19.9 | G5: 1 | H5: =ROUND(G5*F5,2) | I5: =IF(ROUND(H5-D5,2)=0,1,0) | J5: =IF(F5="","none",IF(G5=1,"carte","multiple"))
A6: 2022-04-14 | B6: 12:25 | C6: 2938 | D6: 22 | E6: 36685 | F6: 0.4 | G6: 55 | H6: =ROUND(G6*F6,2) | I6: =IF(ROUND(H6-D6,2)=0,1,0) | J6: =IF(F6="","none",IF(G6=1,"carte","multiple"))
A7: 2022-04-14 | B7: 12:25 | C7: 2938 | D7: 3.9 | E7: 36686 | F7: 3.9 | G7: 1 | H7: =ROUND(G7*F7,2) | I7: =IF(ROUND(H7-D7,2)=0,1,0) | J7: =IF(F7="","none",IF(G7=1,"carte","multiple"))
A8: 2022-04-14 | B8: 12:25 | C8: 2938 | D8: 4 | E8: 36687 | F8: 4 | G8: 1 | H8: =ROUND(G8*F8,2) | I8: =IF(ROUND(H8-D8,2)=0,1,0) | J8: =IF(F8="","none",IF(G8=1,"carte","multiple"))
A9: 2022-04-14 | B9: 13:35 | C9: 2938 | D9: 7.6 | E9: 36688 | F9: 7.6 | G9: 1 | H9: =ROUND(G9*F9,2) | I9: =IF(ROUND(H9-D9,2)=0,1,0) | J9: =IF(F9="","none",IF(G9=1,"carte","multiple"))
A10: 2022-04-14 | B10: 13:35 | C10: 2938 | D10: 19 | E10: 36689 | F10: 19 | G10: 1 | H10: =ROUND(G10*F10,2) | I10: =IF(ROUND(H10-D10,2)=0,1,0) | J10: =IF(F10="","none",IF(G10=1,"carte","multiple"))
A11: 2022-04-14 | B11: 13:35 | C11: 2938 | D11: 17.6 | E11: 36690 | F11: 17.6 | G11: 1 | H11: =ROUND(G11*F11,2) | I11: =IF(ROUND(H11-D11,2)=0,1,0) | J11: =IF(F11="","none",IF(G11=1,"carte","multiple"))
A12: 2022-04-14 | B12: 13:35 | C12: 2938 | D12: 4.4 | E12: 36691 | F12: 0.4 | G12: 11 | H12: =ROUND(G12*F12,2) | I12: =IF(ROUND(H12-D12,2)=0,1,0) | J12: =IF(F12="","none",IF(G12=1,"carte","multiple"))
A13: 2022-04-14 | B13: 18:35 | C13: 2938 | D13: 16.9 | E13: 36693 | F13: 16.9 | G13: 1 | H13: =ROUND(G13*F13,2) | I13: =IF(ROUND(H13-D13,2)=0,1,0) | J13: =IF(F13="","none",IF(G13=1,"carte","multiple"))
A14: 2022-04-14 | B14: 18:35 | C14: 2938 | D14: 15.9 | E14: 36694 | F14: 15.9 | G14: 1 | H14: =ROUND(G14*F14,2) | I14: =IF(ROUND(H14-D14,2)=0,1,0) | J14: =IF(F14="","none",IF(G14=1,"carte","multiple"))
... A353: 2022-04-22 | B353: 18:13 | C353: 2945 | D353: 11 | E353: 37054 | F353: 11 | G353: 1 | H353: =ROUND(G353*F353,2) | I353: =IF(ROUND(H353-D353,2)=0,1,0) | J353: =IF(F353="","none",IF(G353=1,"carte","multiple"))
A354: 2022-04-22 | B354: 18:20 | C354: 2945 | D354: 0 | E354: 37055 | J354: =IF(F354="","none",IF(G354=1,"carte","multiple"))
A355: 2022-04-22 | B355: 18:20 | C355: 2945 | D355: 19 | E355: 37056 | F355: 19 | G355: 1 | H355: =ROUND(G355*F355,2) | I355: =IF(ROUND(H355-D355,2)=0,1,0) | J355: =IF(F355="","none",IF(G355=1,"carte","multiple"))
A356: 2022-04-22 | B356: 18:57 | C356: 2945 | D356: 4.2 | E356: 37057 | F356: 4.2 | G356: 1 | H356: =ROUND(G356*F356,2) | I356: =IF(ROUND(H356-D356,2)=0,1,0) | J356: =IF(F356="","none",IF(G356=1,"carte","multiple"))
A357: 2022-04-22 | B357: 18:57 | C357: 2945 | D357: 7.8 | E357: 37058 | F357: 7.8 | G357: 1 | H357: =ROUND(G357*F357,2) | I357: =IF(ROUND(H357-D357,2)=0,1,0) | J357: =IF(F357="","none",IF(G357=1,"carte","multiple"))
A358: 2022-04-22 | B358: 19:27 | C358: 2945 | D358: 17.6 | E358: 37059 | F358: 17.6 | G358: 1 | H358: =ROUND(G358*F358,2) | I358: =IF(ROUND(H358-D358,2)=0,1,0) | J358: =IF(F358="","none",IF(G358=1,"carte","multiple"))
A359: 2022-04-22 | B359: 19:28 | C359: 2945 | D359: 19 | E359: 37060 | F359: 19 | G359: 1 | H359: =ROUND(G359*F359,2) | I359: =IF(ROUND(H359-D359,2)=0,1,0) | J359: =IF(F359="","none",IF(G359=1,"carte","multiple"))
A360: 2022-04-22 | B360: 19:43 | C360: 2945 | D360: 3.9 | E360: 37061 | F360: 3.9 | G360: 1 | H360: =ROUND(G360*F360,2) | I360: =IF(ROUND(H360-D360,2)=0,1,0) | J360: =IF(F360="","none",IF(G360=1,"carte","multiple"))
A361: 2022-04-22 | B361: 20:56 | C361: 2945 | D361: 14.4 | E361: 37062 | F361: 0.4 | G361: 36 | H361: =ROUND(G361*F361,2) | I361: =IF(ROUND(H361-D361,2)=0,1,0) | J361: =IF(F361="","none",IF(G361=1,"carte","multiple"))
A362: 2022-04-22 | B362: 20:56 | C362: 2945 | D362: 4.4 | E362: 37063 | F362: 0.4 | G362: 11 | H362: =ROUND(G362*F362,2) | I362: =IF(ROUND(H362-D362,2)=0,1,0) | J362: =IF(F362="","none",IF(G362=1,"carte","multiple"))
A363: 2022-04-22 | B363: 20:56 | C363: 2945 | D363: 10.4 | E363: 37064 | F363: 0.4 | G363: 26 | H363: =ROUND(G363*F363,2) | I363: =IF(ROUND(H363-D363,2)=0,1,0) | J363: =IF(F363="","none",IF(G363=1,"carte","multiple"))
A364: 2022-04-22 | B364: 20:56 | C364: 2945 | D364: 3.6 | E364: 37065 | F364: 3.6 | G364: 1 | H364: =ROUND(G364*F364,2) | I364: =IF(ROUND(H364-D364,2)=0,1,0) | J364: =IF(F364="","none",IF(G364=1,"carte","multiple"))
A365: 2022-04-22 | B365: 20:56 | C365: 2945 | D365: 19.4 | E365: 37066 | F365: 9.7 | G365: 2 | H365: =ROUND(G365*F365,2) | I365: =IF(ROUND(H365-D365,2)=0,1,0) | J365: =IF(F365="","none",IF(G365=1,"carte","multiple"))
A366: 2022-04-22 | B366: 20:56 | C366: 2945 | D366: 5.9 | E366: 37067 | F366: 5.9 | G366: 1 | H366: =ROUND(G366*F366,2) | I366: =IF(ROUND(H366-D366,2)=0,1,0) | J366: =IF(F366="","none",IF(G366=1,"carte","multiple"))
... A690: 2022-05-06 | B690: 20:08 | C690: 2954 | D690: 8.4 | E690: 37420 | F690: 8.4 | G690: 1 | H690: =ROUND(G690*F690,2) | I690: =IF(ROUND(H690-D690,2)=0,1,0) | J690: =IF(F690="","none",IF(G690=1,"carte","multiple"))
A691: 2022-05-06 | B691: 20:17 | C691: 2954 | D691: 0 | E691: 37422 | J691: =IF(F691="","none",IF(G691=1,"carte","multiple"))
A692: 2022-05-06 | B692: 20:17 | C692: 2954 | D692: 17.6 | E692: 37423 | F692: 17.6 | G692: 1 | H692: =ROUND(G692*F692,2) | I692: =IF(ROUND(H692-D692,2)=0,1,0) | J692: =IF(F692="","none",IF(G692=1,"carte","multiple"))
A693: 2022-05-06 | B693: 20:17 | C693: 2954 | D693: 17.6 | E693: 37424 | F693: 17.6 | G693: 1 | H693: =ROUND(G693*F693,2) | I693: =IF(ROUND(H693-D693,2)=0,1,0) | J693: =IF(F693="","none",IF(G693=1,"carte","multiple"))
A694: 2022-05-06 | B694: 20:17 | C694: 2954 | D694: 0 | E694: 37425 | J694: =IF(F694="","none",IF(G694=1,"carte","multiple"))
A695: 2022-05-06 | B695: 20:30 | C695: 2954 | D695: 3.9 | E695: 37426 | F695: 3.9 | G695: 1 | H695: =ROUND(G695*F695,2) | I695: =IF(ROUND(H695-D695,2)=0,1,0) | J695: =IF(F695="","none",IF(G695=1,"carte","multiple"))
A696: 2022-05-06 | B696: 20:30 | C696: 2954 | D696: 6.5 | E696: 37427 | F696: 6.5 | G696: 1 | H696: =ROUND(G696*F696,2) | I696: =IF(ROUND(H696-D696,2)=0,1,0) | J696: =IF(F696="","none",IF(G696=1,"carte","multiple"))
A697: 2022-05-06 | B697: 20:37 | C697: 2954 | D697: 7.9 | E697: 37428 | F697: 7.9 | G697: 1 | H697: =ROUND(G697*F697,2) | I697: =IF(ROUND(H697-D697,2)=0,1,0) | J697: =IF(F697="","none",IF(G697=1,"carte","multiple"))
A698: 2022-05-06 | B698: 20:37 | C698: 2954 | D698: 39.5 | E698: 37429 | F698: 39.5 | G698: 1 | H698: =ROUND(G698*F698,2) | I698: =IF(ROUND(H698-D698,2)=0,1,0) | J698: =IF(F698="","none",IF(G698=1,"carte","multiple"))
A699: 2022-05-07 | B699: 10:38 | C699: 2955 | D699: 5.9 | E699: 37432 | F699: 5.9 | G699: 1 | H699: =ROUND(G699*F699,2) | I699: =IF(ROUND(H699-D699,2)=0,1,0) | J699: =IF(F699="","none",IF(G699=1,"carte","multiple"))
A700: 2022-05-07 | B700: 11:17 | C700: 2955 | D700: 15 | E700: 37433 | F700: 15 | G700: 1 | H700: =ROUND(G700*F700,2) | I700: =IF(ROUND(H700-D700,2)=0,1,0) | J700: =IF(F700="","none",IF(G700=1,"carte","multiple"))
A701: 2022-05-07 | B701: 11:17 | C701: 2955 | D701: 19.9 | E701: 37434 | F701: 19.9 | G701: 1 | H701: =ROUND(G701*F701,2) | I701: =IF(ROUND(H701-D701,2)=0,1,0) | J701: =IF(F701="","none",IF(G701=1,"carte","multiple"))
...
