Workbook

Sheet Sources
A1: SOURCES — données brutes utilisées (centilitres sauf mention)
A2: Achats : 199 factures du fournisseur Franche-Comté Boissons Services, rattachées par CODE ARTICLE et par date de facture. Ventes : annexes de caisse B/D des trois exercices (ANNEXE-B1/C1 2022-2023 ; ANNEXE-B2/D2 2023-2024 ; ANNEXE-B3/D3 2024-2025), format de service × contenance. Stocks : inventaires physiques de clôture (31/03). Prix de vente : ANNEXE-B1. Les volumes 2023-2024 et 2024-2025 ont été revérifiés sur les annexes D2/D3 (synthèse produit) : 5 310 cl et 4 683 cl, identiques aux totaux des annexes du service du 18/05/2026 (p. 63 et p. 77).
A4: 1. ACHATS FACTURÉS (bouteilles de 75 cl)
A5: Référence (code fournisseur) | B5: Bouton de caisse | C5: Exercice | D5: Bouteilles facturées | E5: Contenance (cl)
A6: Bordeaux Supérieur, Château Grand Renom (661236) | B6: BORD. MOUTON CADET | C6: 2022-2023 | D6: 11 | E6: 75
A7: Bordeaux Supérieur, Château Grand Renom (661236) | B7: BORD. MOUTON CADET | C7: 2023-2024 | D7: 0 | E7: 75
A8: Bordeaux Supérieur, Château Grand Renom (661236) | B8: BORD. MOUTON CADET | C8: 2024-2025 | D8: 0 | E8: 75
A9: HC de Nuits blanc, Lupé Cholet 2017 (601416) | B9: H.COTES DE NUITS | C9: 2022-2023 | D9: 24 | E9: 75
A10: HC de Nuits blanc, Lupé Cholet 2017 (601416) | B10: H.COTES DE NUITS | C10: 2023-2024 | D10: 0 | E10: 75
A11: HC de Nuits blanc, Lupé Cholet 2017 (601416) | B11: H.COTES DE NUITS | C11: 2024-2025 | D11: 0 | E11: 75
A12: HC de Beaune blanc, Domaine Germain (600425) | B12: PICHET C.DE BEAUNE B | C12: 2022-2023 | D12: 1 | E12: 75
A13: HC de Beaune blanc, Domaine Germain (600425) | B13: PICHET C.DE BEAUNE B | C13: 2023-2024 | D13: 0 | E13: 75
A14: HC de Beaune blanc, Domaine Germain (600425) | B14: PICHET C.DE BEAUNE B | C14: 2024-2025 | D14: 0 | E14: 75
A15: HC de Beaune rouge, Domaine Germain (601667/601346/630253/601199) | B15: H.C. BEAUNE (btl/verre/pichet) | C15: 2022-2023 | D15: 110 | E15: 75
A16: HC de Beaune rouge, Domaine Germain | B16: H.C. BEAUNE (btl/verre/pichet) | C16: 2023-2024 | D16: 85 | E16: 75
A17: HC de Beaune rouge, Domaine Germain | B17: H.C. BEAUNE (btl/verre/pichet) | C17: 2024-2025 | D17: 74 | E17: 75
A19: 2. VENTES ENREGISTRÉES EN CAISSE (format de service × contenance)
A20: Référence | B20: Format | C20: Exercice | D20: Quantité (unités) | E20: Contenance unitaire (cl)
A21: HC de Beaune rouge | B21: Bouteille (dont demi) | C21: 2022-2023 | D21: 42.5 | E21: 75
A22: HC de Beaune rouge | B22: Verre | C22: 2022-2023 | D22: 182 | E22: 15
A23: HC de Beaune rouge | B23: Pichet 50 cl | C23: 2022-2023 | D23: 26 | E23: 50
A24: HC de Beaune rouge | B24: Bouteille | C24: 2023-2024 | D24: 26 | E24: 75
A25: HC de Beaune rouge | B25: Verre | C25: 2023-2024 | D25: 124 | E25: 15
A26: HC de Beaune rouge | B26: Pichet 50 cl | C26: 2023-2024 | D26: 30 | E26: 50
A27: HC de Beaune rouge | B27: Bouteille (dont demi) | C27: 2024-2025 | D27: 22.5 | E27: 75
A28: HC de Beaune rouge | B28: Verre | C28: 2024-2025 | D28: 103 | E28: 15
A29: HC de Beaune rouge | B29: Pichet 50 cl | C29: 2024-2025 | D29: 29 | E29: 50
A30: Bordeaux Supérieur (bouton MOUTON CADET) | B30: Bouteille | C30: 2022-2023 | D30: 9 | E30: 75
A31: HC de Nuits blanc | B31: Bouteille | C31: 2022-2023 | D31: 3 | E31: 75
A32: HC de Beaune blanc (bouton PICHET C.DE BEAUNE B) | B32: Pichet 50 cl | C32: 2022-2023 | D32: 6 | E32: 50
... A34: HC de Beaune blanc (bouton PICHET C.DE BEAUNE B) | B34: Pichet 50 cl | C34: 2024-2025 | D34: 0 | E34: 50
A36: 3. STOCKS DE CLÔTURE (inventaires physiques 31/03)
A37: Référence | B37: Date de clôture | C37: Bouteilles inventoriées | D37: Contenance (cl) | E37: Note
A38: Bordeaux Supérieur (MOUTON CADET) | B38: 31/03/2023 | C38: 1 | D38: 75 | E38: porté à l'inventaire 2022-2023
A39: HC de Beaune rouge | B39: 31/03/2023 | C39: 6 | D39: 75 | E39: porté à l'inventaire 2022-2023
A40: HC de Beaune rouge | B40: 31/03/2024 | C40: n/d | D40: 75 | E40: non inventorié (aucune ligne à ce libellé) — n'est pas un stock nul
A41: HC de Beaune rouge | B41: 31/03/2025 | C41: 8 | D41: 75 | E41: porté à l'inventaire 2024-2025
A42: HC de Nuits blanc | B42: 31/03/2023..2025 | C42: n/d | D42: 75 | E42: non inventorié sous aucun libellé (cherché par libellé et par prix 12,22 €)
A43: HC de Beaune blanc | B43: 31/03/2023..2025 | C43: n/d | D43: 75 | E43: non inventorié sous aucun libellé (cherché par libellé et par prix 9,95 €)
A44: Ouverture 01/04/2022 (tous) | B44: 01/04/2022 | C44: n/d | D44: 75 | E44: AUCUN inventaire d'ouverture produit — bilan matière fermé impossible pour 2022-2023
...

Sheet Calcul
A1: CALCUL — tous les résultats sont obtenus par formule (bilan par vin : achats − ventes − stock)
A3: A. ACHATS en cl (= bouteilles × contenance, renvoi à Sources)
A4: Référence | B4: Exercice | C4: Achats (cl) = D×E Sources
A5: Bordeaux Supérieur, Château Grand Renom (661236) | B5: 2022-2023 | C5: =Sources!D6*Sources!E6
A6: Bordeaux Supérieur, Château Grand Renom (661236) | B6: 2023-2024 | C6: =Sources!D7*Sources!E7
A7: Bordeaux Supérieur, Château Grand Renom (661236) | B7: 2024-2025 | C7: =Sources!D8*Sources!E8
A8: HC de Nuits blanc, Lupé Cholet 2017 (601416) | B8: 2022-2023 | C8: =Sources!D9*Sources!E9
A9: HC de Nuits blanc, Lupé Cholet 2017 (601416) | B9: 2023-2024 | C9: =Sources!D10*Sources!E10
A10: HC de Nuits blanc, Lupé Cholet 2017 (601416) | B10: 2024-2025 | C10: =Sources!D11*Sources!E11
A11: HC de Beaune blanc, Domaine Germain (600425) | B11: 2022-2023 | C11: =Sources!D12*Sources!E12
A12: HC de Beaune blanc, Domaine Germain (600425) | B12: 2023-2024 | C12: =Sources!D13*Sources!E13
A13: HC de Beaune blanc, Domaine Germain (600425) | B13: 2024-2025 | C13: =Sources!D14*Sources!E14
A14: HC de Beaune rouge, Domaine Germain (601667/601346/630253/601199) | B14: 2022-2023 | C14: =Sources!D15*Sources!E15
A15: HC de Beaune rouge, Domaine Germain | B15: 2023-2024 | C15: =Sources!D16*Sources!E16
A16: HC de Beaune rouge, Domaine Germain | B16: 2024-2025 | C16: =Sources!D17*Sources!E17
A18: B. VENTES en cl (= quantité × contenance, renvoi à Sources ; somme par réf/exercice)
A19: Référence | B19: Exercice | C19: Ventes (cl) = Σ(Q×contenance) | D19: Détail
A20: HC de Beaune rouge | B20: Bouteille (dont demi) — 2022-2023 | C20: =Sources!D21*Sources!E21
A21: HC de Beaune rouge | B21: Verre — 2022-2023 | C21: =Sources!D22*Sources!E22
A22: HC de Beaune rouge | B22: Pichet 50 cl — 2022-2023 | C22: =Sources!D23*Sources!E23
A23: HC de Beaune rouge | B23: Bouteille — 2023-2024 | C23: =Sources!D24*Sources!E24
A24: HC de Beaune rouge | B24: Verre — 2023-2024 | C24: =Sources!D25*Sources!E25
A25: HC de Beaune rouge | B25: Pichet 50 cl — 2023-2024 | C25: =Sources!D26*Sources!E26
A26: HC de Beaune rouge | B26: Bouteille (dont demi) — 2024-2025 | C26: =Sources!D27*Sources!E27
A27: HC de Beaune rouge | B27: Verre — 2024-2025 | C27: =Sources!D28*Sources!E28
A28: HC de Beaune rouge | B28: Pichet 50 cl — 2024-2025 | C28: =Sources!D29*Sources!E29
A29: Bordeaux Supérieur (bouton MOUTON CADET) | B29: Bouteille — 2022-2023 | C29: =Sources!D30*Sources!E30
A30: HC de Nuits blanc | B30: Bouteille — 2022-2023 | C30: =Sources!D31*Sources!E31
A31: HC de Beaune blanc (bouton PICHET C.DE BEAUNE B) | B31: Pichet 50 cl — 2022-2023 | C31: =Sources!D32*Sources!E32
... A33: HC de Beaune blanc (bouton PICHET C.DE BEAUNE B) | B33: Pichet 50 cl — 2024-2025 | C33: =Sources!D34*Sources!E34
A35: C. BILAN PAR VIN ET PAR EXERCICE (bilan ouvert : achats − ventes)
A36: Vin / référence | B36: Exercice | C36: Achats (cl) | D36: Ventes (cl) | E36: Achats − ventes (cl)
A37: Bordeaux Supérieur (MOUTON CADET) | B37: 2022-2023 | C37: =Calcul!C5 | D37: =Calcul!C29 | E37: =C37-D37
A38: HC de Nuits blanc (Lupé Cholet) | B38: 2022-2023 | C38: =Calcul!C8 | D38: =Calcul!C30 | E38: =C38-D38
A39: HC de Beaune blanc (Domaine Germain) | B39: 2022-2023 | C39: =Calcul!C11 | D39: =Calcul!C31 | E39: =C39-D39
A40: HC de Beaune blanc (Domaine Germain) | B40: 2023-2024 | C40: =Calcul!C12 | D40: =Calcul!C32 | E40: =C40-D40
A41: HC de Beaune blanc (Domaine Germain) | B41: 2024-2025 | C41: =Calcul!C13 | D41: =Calcul!C33 | E41: =C41-D41
A42: HC de Beaune rouge (Domaine Germain) | B42: 2022-2023 | C42: =Calcul!C14 | D42: =SUM(Calcul!C20:Calcul!C22) | E42: =C42-D42
A43: HC de Beaune rouge (Domaine Germain) | B43: 2023-2024 | C43: =Calcul!C15 | D43: =SUM(Calcul!C23:Calcul!C25) | E43: =C43-D43
A44: HC de Beaune rouge (Domaine Germain) | B44: 2024-2025 | C44: =Calcul!C16 | D44: =SUM(Calcul!C26:Calcul!C28) | E44: =C44-D44
...

Sheet Méthode
A1: MÉTHODE
A3: Objet | B3: Point 10 de la réponse du 04/09/2026 (p. 74-75) : vérifier, référence par référence et exercice par exercice, l'existence de « ventes sans achat », et traiter honnêtement le bilan matière (achats − ventes − stock).
A4: Achats | B4: 199 factures du fournisseur Franche-Comté Boissons Services, rattachées par CODE ARTICLE (et non par libellé) et par date de facture à l'exercice 01/04→31/03. La même référence est facturée sous des désignations abrégées ou des millésimes différents : c'est le rattachement par code qui porte les achats de Bordeaux Supérieur à 11 bouteilles (et non 9) et le HC de Beaune rouge à 269 bouteilles sur trois ans (et non ≈245).
A5: Ventes caisse | B5: Annexes de caisse C/D. Contenances de service : verre 15 cl, pichet 50 cl, bouteille 75 cl. La ligne « Bouteille » du HC de Beaune rouge porte des demi-bouteilles (37,5 cl) : la caisse enregistre 42,5 unités-bouteille en 2022-2023 et 22,5 en 2024-2025, d'où 42,5×75 = 3 187,5 ≈ 3 188 cl et 22,5×75 = 1 687,5 ≈ 1 688 cl. Le « +38 cl » relevé provient de l'arrondi de 42,5 à 42 (et 22,5 à 22) dans un tableau de synthèse antérieur : 0,5 bouteille × 75 = 37,5 ≈ 38 cl. Les volumes 7 218 cl et 4 683 cl sont donc exacts et dérivables.
A6: Stocks | B6: Inventaires physiques de clôture (31/03/2023, 31/03/2024, 31/03/2025). « non inventorié (aucune ligne à ce libellé) » distingue l'absence de ligne d'un stock nul. AUCUN inventaire d'ouverture au 01/04/2022 n'a été produit : un bilan matière FERMÉ (ouverture + achats − ventes = clôture) est donc impossible à établir avec certitude pour l'exercice 2022-2023.
A7: Bilan Mouton Cadet | B7: Bordeaux Supérieur 2022-2023 : 11 achetées − 9 vendues = 2 attendues en stock ; l'inventaire n'en porte qu'1. Écart = 1 bouteille (75 cl) sortie sans vente enregistrée. Ce n'est PAS une « vente sans achat » (le sens est inverse : plus d'achats que de ventes), mais une sortie non tracée (casse, offert, consommation, ou vente non enregistrée) que nous ne pouvons pas documenter. Exposition maximale si requalifiée en vente : 30,00 € HT (36,00 € TTC, ANNEXE-B1).
A8: Beaune blanc | B8: HC de Beaune blanc : 75 cl achetés (1 bouteille) pour 450 cl vendus au pichet sur trois exercices, soit 375 cl au-delà des achats sous ce code. Ces pichets ont été tirés sur le sur-stock de HC de Nuits blanc (1 800 cl achetés, 225 cl vendus) mais enregistrés sous le bouton « PICHET C.DE BEAUNE B » : c'est un défaut de paramétrage du bouton, que nous ne contestons pas. En volume, les deux blancs regroupés donnent 1 875 cl achetés pour 675 cl vendus (achats = 2,8× ventes) ; la recette des 375 cl est enregistrée (pas de CA occulté).
A9: Achats occultes | B9: La comparaison « achats facturés ≥ ventes » n'exclut pas, à elle seule, l'hypothèse d'achats réglés en espèces hors facture : un tel achat n'apparaîtrait ni dans les factures ni, s'il était revendu au comptant sans ticket, dans la caisse. La seule démonstration positive de l'absence d'achat occulte relèverait d'un contrôle des fournisseurs, hors de portée du contribuable. Si la comptabilité est écartée pour graves irrégularités, l'article L. 192 al. 2 du LPF renverse la charge de la preuve sur le contribuable (limite assumée).
A10: Tableaux p.75 | B10: Transcription fidèle des trois tableaux, puis recalcul. Écarts et taux recalculés : ex.1 = 717 cl (15,31 %) ; ex.2 et 3 = 11 960 cl (11 960/18 260 = 65,498 %, soit 65,50 % arrondi ; le service écrit 65,49 %). Les tableaux des exercices 2 et 3 sont identiques au centilitre près. La ligne « Beaune BLANC » porte 12 950 cl, non reproductible depuis la caisse (150 cl en 2023-2024, 0 en 2024-2025) ; la Proposition (p. 32) limite elle-même cette anomalie au « seul » exercice clos le 31/03/2024, alors que les tableaux la répètent sur 2024-2025.
A11: Sources de données | B11: Achats : src/data/factures-fournisseur (199 factures). Ventes : annexes C/D de la caisse (2022-2023 : annexes B1/C1 jointes ; 2023-2024 et 2024-2025 : extraction de la réponse n°1, annexes primaires C-2/D-2 et C-3/D-3 à produire). Stocks : inventaires 31/03/2023-2024-2025. Prix : ANNEXE-B1.
A12: Généré par | B12: Pièce R2 à formules (onglets Sources / Calcul / Méthode). Tous les résultats de l'onglet Calcul sont des formules renvoyant à l'onglet Sources.
A13: Code 2091 | B13: Les 12 950 cl de « Beaune BLANC » sont la somme des lignes du code de caisse 2091 dans l'annexe D-2 du service : 3 pichets « C.DE BEAUNE B » à 30 € (150 cl) et 256 pichets « PICHET ROSE » à 10,49 € de moyenne (12 800 cl). Le code 2091 a été réaffecté au rosé maison le 05/05/2023 (dernière vente Beaune B le 30/04/2023). Le service a imprimé cette ligne de 256 pichets, avec son prix de 10,49 €, sous le libellé « PICHET C.DE BEAUNE B » (annexe 18/05 p. 64) et l'a rangée dans un bloc à disponible nul. Le rosé maison est acheté en BIB (23 BIB de 10 L en 2023-2024).
A14: p. 75 | B14: Les volumes imprimés p. 75 sont ceux des annexes du 18/05 : « exercice 1 » = 5 400 / 4 683 = 2024-2025 (p. 77) ; « exercice 2 » = 6 300 / 5 310 = 2023-2024 (p. 63) ; « exercice 3 » = copie de l'exercice 2. Le vrai 2022-2023 (8 475 / 7 255, p. 48) n'y figure pas.
A15: Annexes caisse | B15: Les annexes B/D des trois exercices sont disponibles ; les volumes 2023-2024 (5 310 cl) et 2024-2025 (4 683 cl) sont vérifiés sur D2/D3 et coïncident avec les annexes du service.

Sheet Code 2091
A1: D'OÙ VIENNENT LES 12 950 cl : le code de caisse 2091 porte deux libellés successifs
A2: Source : ANNEXE-D2_synthese-produit_2023-2024.xls (fichier du service, colonnes Ref_prd / Lib_ticket / Uprice_wt / Prix moyen / Qte / Tot_rem Ttc), lignes du code 2091 ; ANNEXE-B2 (lignes de tickets) pour les dates ; annexe du 18/05/2026 p. 64 pour la lecture faite par le service.
A4: A. Lignes du code 2091 dans l'annexe D-2 (2023-2024) | B4: Prix unitaire TTC (€) | C4: Quantité | D4: Total TTC (€) = prix × qté | E4: Contenance retenue par le service (cl) | F4: Volume (cl) = qté × contenance | G4: Lecture
A5: PICHET C.DE BEAUNE B (ligne 145 de D-2) | B5: 30 | C5: 3 | D5: =B5*C5 | E5: 50 | F5: =C5*E5 | G5: pichet de Hautes Côtes de Beaune blanc, 30 € : réel
A6: PICHET ROSE (ligne 146 de D-2) | B6: 8.5 | C6: 1 | D6: =B6*C6 | E6: 50 | F6: =C6*E6 | G6: pichet de rosé maison (BIB), même code 2091
A7: PICHET ROSE (ligne 147 de D-2) | B7: 10.5 | C7: 255 | D7: =B7*C7 | E7: 50 | F7: =C7*E7 | G7: pichet de rosé maison (BIB), même code 2091
A8: TOTAL code 2091 (ce que le service a lu comme « Haute côte de Beaune BLANC ») | C8: =SUM(C5:C7) | D8: =SUM(D5:D7) | F8: =SUM(F5:F7)
A9: dont PICHET ROSE : quantité, total TTC, volume | C9: =C6+C7 | D9: =D6+D7 | F9: =F6+F7
A10: Prix moyen du PICHET ROSE (€) = total ÷ quantité (le service imprime « 10,49 € », annexe 18/05 p. 64) | B10: =D9/C9
A11: Part du rosé dans les 12 950 cl (le service imprime « 98,84 % ») | B11: =F9/F8
A12: Part du vrai Beaune blanc dans les 12 950 cl (le service imprime « 1,16 % ») | B12: =F5/F8
A13: Contrôle : total = 12 950 cl imprimé p. 75 et p. 64 ? | B13: =IF(F8=12950,"OUI","NON")
A15: B. Chronologie du code 2091 (ANNEXE-B2, lignes de tickets 2023-2024) | B15: Date | C15: Libellé | D15: Lignes | E15: Unités | F15: Montant TTC (€)
A16: Dernière vente sous le libellé « PICHET C.DE BEAUNE B » | B16: 30/04/2023 | C16: PICHET C.DE BEAUNE B | D16: 3 | E16: 3 | F16: 90
A17: Première vente sous le libellé « PICHET ROSE » (même code 2091) | B17: 05/05/2023 | C17: PICHET ROSE
A18: Dernière vente « PICHET ROSE » de l'exercice | B18: 31/03/2024 | C18: PICHET ROSE | D18: 257 | E18: 262 | F18: 2665
A19: Note : l'annexe D-2 (synthèse) retient 256 unités / 2 686,00 € pour le rosé (nettes de remises et demi-pichets) ; l'annexe B-2 (lignes) en compte 257 lignes / 262 unités / 2 665,00 €. C'est la lecture D-2 (256 ; 10,49 €) que le service a imprimée.
A20: 2024-2025 (ANNEXE-D3, lignes 149-150) : le code 2091 ne porte plus que « PICHET ROSE » | B20: 7.2 | C20: 1 | D20: =B20*C20
B21: 10.5 | C21: 191.5 | D21: =B21*C21
A22: Total pichets rosé 2024-2025 (unités ; volume à 50 cl) | C22: =C20+C21 | F22: =C22*50
A23: Pichets « C.DE BEAUNE B » vendus en 2024-2025 | C23: 0 | F23: =C23*50
A25: C. Le rosé maison est acheté (BIB), factures FCBS par exercice | B25: BIB 10 L (unités) | C25: BIB 5 L / 3 L (unités) | D25: Volume acheté (cl) | E25: Pichets rosé vendus (unités) | F25: Volume vendu (cl) = unités × 50 | G25: Couverture achats ÷ ventes
A26: 2023-2024 : BIB COTES DE PROV ROSE 10 L (code 603042) = 23 ; le service lit lui-même « BIB 10 L Provence Rosé 23 » + « BIB 5 L 8 » (annexe 18/05, tableau des achats 2023-2024) | B26: 23 | C26: 0 | D26: =B26*1000+C26*500 | E26: =C9 | F26: =E26*50 | G26: =D26/F26
A27: 2024-2025 : BIB COTES DE PROVENCE 10 L ROSE (601956) = 16 ; BIB GARDILLES ROSE 10 L (605168) = 1 ; BIB 3 L ROSE (665048) = 4 | B27: 17 | C27: 4 | D27: =B27*1000+C27*300 | E27: =C22 | F27: =E27*50 | G27: =D27/F27
A28: Lecture : les 256 pichets de 2023-2024 sont du rosé maison tiré de BIB achetés et facturés ; ils n'ont rien à voir avec le Hautes Côtes de Beaune blanc. Le service les a comptés dans le bloc « Beaune blanc » (disponible 0) et non dans le bloc « pichets de vin maison » où figure le disponible des BIB rosé : d'où 12 800 cl « vendus sans achat ».
A30: D. Test de prix | B30: Prix (€ TTC) | C30: Rapport
A31: Pichet 50 cl de Hautes Côtes de Beaune blanc (ANNEXE-B1/B2, code 2091 jusqu'au 30/04/2023) | B31: 30
A32: Prix moyen imprimé par le service pour la ligne de 256 pichets (annexe 18/05 p. 64) | B32: =B10
A33: Rapport prix Beaune blanc ÷ prix de la ligne de 256 : un pichet de Beaune à 30 € ne se vend pas 10,49 € | C33: =B31/B32

Sheet p75 vs annexes
A1: LES VOLUMES DE LA PAGE 75 (04/09/2026) RAPPROCHÉS DES ANNEXES « PAR PRODUIT » DU 18/05/2026
A2: Sources : réponse du service du 04/09/2026 p. 75 (trois tableaux) ; proposition du 18/05/2026, annexes boissons : tableau des achats/stocks/disponibles (p. 29 pour 2022-2023, puis 2023-2024 et 2024-2025) et blocs Haute côte Beaune rouge (p. 48, p. 63, p. 77), Bordeaux (p. 49, p. 63, p. 77), Haute côte Nuit blanc (p. 49, p. 64, p. 78). Valeurs saisies = lecture des annexes ; résultats = formules.
A4: A. Haute côte de Beaune ROUGE, exercice réel (annexes 18/05) | B4: Achats FCBS (bt) | C4: Stock 31/03 N-1 (bt) | D4: Stock 31/03 N (bt) | E4: Disponible (bt) = achats + SI − SF | F4: Disponible (cl) = bt × 75 | G4: Caisse (cl) selon l'annexe | H4: Disponible − caisse (cl)
A5: 2022-2023 (p. 29 et p. 48) | B5: 110 | C5: 9 | D5: 6 | E5: =B5+C5-D5 | F5: =E5*75 | G5: 7255 | H5: =F5-G5
A6: 2023-2024 (p. 63) | B6: 85 | C6: 6 | D6: 7 | E6: =B6+C6-D6 | F6: =E6*75 | G6: 5310 | H6: =F6-G6
A7: 2024-2025 (p. 77) | B7: 74 | C7: 7 | D7: 9 | E7: =B7+C7-D7 | F7: =E7*75 | G7: 4683 | H7: =F7-G7
A8: Caisse 2022-2023 = somme des cinq lignes de l'annexe p. 48 : 495 + 2 235 + 1 300 + 2 625 + 600 (les pourcentages imprimés 6,82 / 30,81 / 17,92 / 36,18 / 8,27 % se recalculent sur ce total) | B8: =495+2235+1300+2625+600 | C8: =ROUND(495/B8*100,2) | D8: =ROUND(2235/B8*100,2) | E8: =ROUND(1300/B8*100,2) | F8: =ROUND(2625/B8*100,2) | G8: =ROUND(600/B8*100,2)
A9: Part « disparue » 2022-2023 selon le service (14,4 % dans son tableau des disparus) = (disponible − caisse) ÷ disponible | B9: =H5/F5
A11: B. Ce que la page 75 imprime, et à quel exercice réel cela correspond | B11: Disponible imprimé (cl) | C11: Caisse imprimée (cl) | D11: Exercice réel ayant ces valeurs | E11: Disponible réel de l'exercice annoncé (cl) | F11: Caisse réelle de l'exercice annoncé (cl) | G11: Même disponible ? | H11: Même caisse ?
A12: « Exercice 1 » (annoncé 2022-2023) | B12: 5400 | C12: 4683 | D12: 2024-2025 (p. 77) | E12: =F5 | F12: =G5 | G12: =IF(B12=E12,"oui","NON") | H12: =IF(C12=F12,"oui","NON")
A13: « Exercice 2 » (annoncé 2023-2024) | B13: 6300 | C13: 5310 | D13: 2023-2024 (p. 63) | E13: =F6 | F13: =G6 | G13: =IF(B13=E13,"oui","NON") | H13: =IF(C13=F13,"oui","NON")
A14: « Exercice 3 » (annoncé 2024-2025) | B14: 6300 | C14: 5310 | D14: 2023-2024 (p. 63), repris une seconde fois | E14: =F7 | F14: =G7 | G14: =IF(B14=E14,"oui","NON") | H14: =IF(C14=F14,"oui","NON")
A15: Contrôle : « Exercice 1 » = valeurs de 2024-2025 ? | B15: =IF(AND(B12=F7,C12=G7),"OUI","non")
A16: Contrôle : « Exercice 3 » = « Exercice 2 » (copie) ? | B16: =IF(AND(B14=B13,C14=C13),"OUI","non")
A18: C. Les trois blocs globalisés, exercice par exercice, avec les disponibles du service et la caisse corrigée du rosé | B18: Disponible rouge (cl) | C18: Disponible Bordeaux (cl) | D18: Disponible blanc (cl) | E18: Caisse rouge (cl) | F18: Caisse Bordeaux (cl) | G18: Caisse blanc corrigée (cl) | H18: Disponible total − caisse totale (cl)
A19: 2022-2023 (annexes p. 29, 48, 49) | B19: =F5 | C19: =10*75 | D19: =42*75 | E19: =G5 | F19: =9*75 | G19: =6*50+3*75 | H19: =B19+C19+D19-E19-F19-G19
A20: 2023-2024 (annexes p. 63, 64) : blanc = 3 pichets réels (150 cl), le rosé (12 800 cl) remis dans son bloc | B20: =F6 | C20: 0 | D20: 0 | E20: =G6 | F20: 0 | G20: ='Code 2091'!F5 | H20: =B20+C20+D20-E20-F20-G20
A21: 2024-2025 (annexes p. 77, 78) | B21: =F7 | C21: 0 | D21: 0 | E21: =G7 | F21: 0 | G21: 0 | H21: =B21+C21+D21-E21-F21-G21
A22: Lecture : une fois le rosé remis dans son bloc, le disponible des trois vins dépasse la caisse sur chacun des trois exercices : il n'existe aucun exercice où « les ventes dépassent le disponible ».
A23: Tableau du service, exercices 2 et 3 : écart imprimé 11 960 cl ; recalcul avec la caisse blanc corrigée (5 310 + 0 + 150 = 5 460 cl) | B23: =E20+F20+G20 | C23: =B20-B23 | D23: =C23/B20
A24: Taux imprimé 65,49 % : recalcul 11 960 ÷ 18 260 | B24: =11960/18260
A26: D. Les deux vins nommés dans le grief, dans les propres annexes du service (18/05, p. 29 et p. 49) | B26: Achats FCBS (bt) | C26: Stock 31/03/22 (bt) | D26: Stock 31/03/23 (bt) | E26: Disponible (bt) | F26: Caisse 2022-2023 (cl) | G26: Disponible (cl) | H26: Disponible − caisse (cl)
A27: « Bordeaux 75 cl » (= Bordeaux Supérieur Château Grand Renom, bouton MOUTON CADET) | B27: 11 | C27: 0 | D27: 1 | E27: =B27+C27-D27 | F27: =9*75 | G27: =E27*75 | H27: =G27-F27
A28: « Haute côte Nuit blanc 75 cl » (= HC de Nuits blanc Lupé Cholet ; le service compte 25 achetées, nos factures 24) | B28: 25 | C28: 17 | D28: 0 | E28: =B28+C28-D28 | F28: =6*50+3*75 | G28: =E28*75 | H28: =G28-F28
A29: Lecture : pour les deux vins cités comme « vendus sans aucun achat », le service avait lui-même identifié les achats (11 et 25 bouteilles) et un disponible supérieur aux ventes. La bouteille de Bordeaux non retrouvée (H27 = 75 cl) est la seule sortie non expliquée.
A30: C-A « reconstitué » de ces blocs dans la méthode par produit du 18/05 : Bordeaux 2022-2023 = 10 bt × 33,82 € TTC ; Nuits blanc 2022-2023 = 36 pichets × 30 € + 18 bt × 39,50 € ; blanc 2023-2024 (disponible 0) = 0 € | B30: =10*33.82 | C30: =B30/1.2 | D30: =36*30+18*39.5 | E30: =D30/1.2 | F30: 0
A31: Lecture : dans cette méthode, un bloc où les ventes dépassent le disponible produit 0 € (disponible nul) ; seuls les blocs à disponible supérieur aux ventes produisent un montant. C'est ce que le service confirme p. 74 : les « ventes sans achat » n'ont entraîné aucun chiffre d'affaires reconstitué.
